Workbook
Name ATUAL_CARGA_TOTAL: RAMAL!$AB$12
Name ATUAL_CORRENTE_MAXIMA: RAMAL!$AB$6
Name ATUAL_DEMANDA_MAXIMA: RAMAL!$AB$8
Name ATUAL_DMDI_MEDIO: RAMAL!$AB$18
Name ATUAL_ENTRADAS_RAMAIS: RAMAL!$A$18:$U$217
Name ATUAL_FATOR_LEITURA_TRAFO: RAMAL!$AB$14
Name AUX_CLAN: DB!$C$35:$F$335
Name COEF_VA: DB!$AA$1:$AG$32
Name CONDUTORES: CABOS[]
Name CONDUTORES: CABOS[]
Name CONDUTORES: CABOS[]
Name CONDUTORES: CABOS[]
Name CONDUTORES: CABOS[]
Name CONDUTORES: CABOS[]
Name CONDUTORES: CABOS[]
Name CONDUTORES: CABOS[]
Name CONDUTORES: CABOS[]
Name CONDUTORES: CABOS[]
Name COORD: COORDENADAS!$B$2:$D$68
Name DEM_ATUAL: DB!$K$7
Name DMDI: RAMAL!$AA$30
Name fator_potencia: DB!$K$2
Name QT_MT: DB!$K$4
Name QT_MTTR: DB!$K$10
Name QT_MTTR2: DB!$K$19
Name QT_MTTR3: DB!$K$26
Name QT_TR: DB!$K$8
Name RAMA_PROJ1: #REF!
Name RAMA_PROJ2: #REF!
Name RAMAIS_ATUAL: RAMAL!$A$18:$Y$217
Name RAMAIS_PROJ1: #REF!
Name T_LINHA_MONO: DB!$M$14
Name T_LINHA_TRF: DB!$M$13
Name TAB_CLAN_DMDI: DB!$A$35:$B$416
Name TAB_MINI_CABO: PROJ1!$R$4:$S$6
Name TR_ATUAL: DB!$K$6

Sheet DB
A1: CONDUTORES | B1: (A) | C1: Resistência | D1: Reatância | E1: α | F1: DIVISOR_R | G1: TEMP_LIM | H1: DELTA_TEMP_30 | I1: K_TERM_30 | P1: I_MIN | Q1: IN_PADRAO | S1: PARAMETRO | T1: VALOR | U1: UNIDADE | W1: CONDUTOR | X1: MATERIAL | Y1: COD_CONDUTOR | AA1: CABO | AB1: V.A/m Trif | AC1: V.A/m mono | AD1: QT MAX TRIF | AE1: QT MAX MONO | AF1: EM 40m
A2: 25 Al - Arm | B2: 95 | C2: 1.5693 | D2: 0.1039 | E2: 0.00403 | F2: =1 + E2 * (G2 - 30) -> 1.2418 | G2: 90 | H2: =G2-30 -> 60 | I2: =IFERROR(B2/H2,0) -> 1.5833333 | J2: fator | K2: 0.92 | P2: =0 -> 0 | Q2: =0 -> 0 | S2: fator_potencia | T2: =K2 -> 0.92 | U2: pu | W2: =INDEX(CABOS[CONDUTORES],1) -> 25 Al - Arm | X2: =IF(ISNUMBER(FIND(" Cu",W2)),"CU",IF(ISNUMBER(FIND(" Al",W2)),"AL",IF(ISNUMBER(FIND(" AA",W2)),"AA","OUTRO"))) -> AL | Y2: =UPPER(SUBSTITUTE(SUBSTITUTE(SUBSTITUTE(SUBSTITUTE(W2," - ","_")," ","_"),"-","_"),".","")) -> 25_AL_ARM | AA2: 25 Al - Arm | AB2: =(SQRT(3)*((CABOS[[#This Row],[DIVISOR_R]]*COS(fator_potencia))+(SIN(fator_potencia)*CABOS[[#This Row],[Reatância]])))/1000 -> 0.0014462113 | AC2: =2*((CABOS[[#This Row],[DIVISOR_R]]*COS(fator_potencia))+(SIN(fator_potencia)*CABOS[[#This Row],[Reatância]]))/1000 -> 0.001669941 | AD2: =CABOS[[#This Row],[(A)]]*AB2 -> 0.13739007 | AE2: =CABOS[[#This Row],[(A)]]*AC2 -> 0.15864439 | AF2: =AD2*40 -> 5.4956029 | AG2: =AF2/220 -> 0.024980013
A3: 50 Al - Arm | B3: 150 | C3: 0.8388 | D3: 0.1039 | E3: 0.00403 | F3: =1 + E3 * (G3 - 20) -> 1.2821 | G3: 90 | H3: =G3-30 -> 60 | I3: =IFERROR(B3/H3,0) -> 2.5 | M3: TRAFO | N3: Z% | P3: =6 -> 6 | Q3: =6 -> 6 | S3: QT_MT | T3: =K4 -> 0.0183 | U3: pu | W3: =INDEX(CABOS[CONDUTORES],2) -> 50 Al - Arm | X3: =IF(ISNUMBER(FIND(" Cu",W3)),"CU",IF(ISNUMBER(FIND(" Al",W3)),"AL",IF(ISNUMBER(FIND(" AA",W3)),"AA","OUTRO"))) -> AL | Y3: =UPPER(SUBSTITUTE(SUBSTITUTE(SUBSTITUTE(SUBSTITUTE(W3," - ","_")," ","_"),"-","_"),".","")) -> 50_AL_ARM | AA3: 50 Al - Arm | AB3: =(SQRT(3)*((CABOS[[#This Row],[DIVISOR_R]]*COS(fator_potencia))+(SIN(fator_potencia)*CABOS[[#This Row],[Reatância]])))/1000 -> 0.0014884985 | AC3: =2*((CABOS[[#This Row],[DIVISOR_R]]*COS(fator_potencia))+(SIN(fator_potencia)*CABOS[[#This Row],[Reatância]]))/1000 -> 0.0017187701 | AD3: =CABOS[[#This Row],[(A)]]*AB3 -> 0.22327478 | AE3: =CABOS[[#This Row],[(A)]]*AC3 -> 0.25781551 | AF3: =AD3*40 -> 8.9309912 | AG3: =AF3/220 -> 0.040595415
A4: 95 Al - Arm | B4: 237 | C4: 0.4197 | D4: 0.098 | E4: 0.00403 | F4: =1 + E4 * (G4 - 20) -> 1.2821 | G4: 90 | H4: =G4-30 -> 60 | I4: =IFERROR(B4/H4,0) -> 3.95 | J4: QT_MT | K4: 0.0183 | M4: 30 | N4: 0.035 | P4: =10 -> 10 | Q4: =10 -> 10 | S4: TR_ATUAL | T4: =K6 -> 150 | U4: kVA | W4: =INDEX(CABOS[CONDUTORES],3) -> 95 Al - Arm | X4: =IF(ISNUMBER(FIND(" Cu",W4)),"CU",IF(ISNUMBER(FIND(" Al",W4)),"AL",IF(ISNUMBER(FIND(" AA",W4)),"AA","OUTRO"))) -> AL | Y4: =UPPER(SUBSTITUTE(SUBSTITUTE(SUBSTITUTE(SUBSTITUTE(W4," - ","_")," ","_"),"-","_"),".","")) -> 95_AL_ARM | AA4: 95 Al - Arm | AB4: =(SQRT(3)*((CABOS[[#This Row],[DIVISOR_R]]*COS(fator_potencia))+(SIN(fator_potencia)*CABOS[[#This Row],[Reatância]])))/1000 -> 0.0014803682 | AC4: =2*((CABOS[[#This Row],[DIVISOR_R]]*COS(fator_potencia))+(SIN(fator_potencia)*CABOS[[#This Row],[Reatância]]))/1000 -> 0.001709382 | AD4: =CABOS[[#This Row],[(A)]]*AB4 -> 0.35084726 | AE4: =CABOS[[#This Row],[(A)]]*AC4 -> 0.40512353 | AF4: =AD4*40 -> 14.033891 | AG4: =AF4/220 -> 0.063790412
A5: 150 Al - Arm | B5: 300 | C5: 0.266 | D5: 0.096 | E5: 0.00403 | F5: =1 + E5 * (G5 - 20) -> 1.2821 | G5: 90 | H5: =G5-30 -> 60 | I5: =IFERROR(B5/H5,0) -> 5 | M5: 45 | N5: 0.035 | P5: =16 -> 16 | Q5: =16 -> 16 | S5: DEM_ATUAL | T5: =K7 -> 127.70729 | U5: kVA | W5: =INDEX(CABOS[CONDUTORES],4) -> 150 Al - Arm | X5: =IF(ISNUMBER(FIND(" Cu",W5)),"CU",IF(ISNUMBER(FIND(" Al",W5)),"AL",IF(ISNUMBER(FIND(" AA",W5)),"AA","OUTRO"))) -> AL | Y5: =UPPER(SUBSTITUTE(SUBSTITUTE(SUBSTITUTE(SUBSTITUTE(W5," - ","_")," ","_"),"-","_"),".","")) -> 150_AL_ARM | AA5: 150 Al - Arm | AB5: =(SQRT(3)*((CABOS[[#This Row],[DIVISOR_R]]*COS(fator_potencia))+(SIN(fator_potencia)*CABOS[[#This Row],[Reatância]])))/1000 -> 0.0014776122 | AC5: =2*((CABOS[[#This Row],[DIVISOR_R]]*COS(fator_potencia))+(SIN(fator_potencia)*CABOS[[#This Row],[Reatância]]))/1000 -> 0.0017061996 | AD5: =CABOS[[#This Row],[(A)]]*AB5 -> 0.44328365 | AE5: =CABOS[[#This Row],[(A)]]*AC5 -> 0.51185987 | AF5: =AD5*40 -> 17.731346 | AG5: =AF5/220 -> 0.080597027
A6: 240 Al - Arm | B6: 395 | C6: 0.1665 | D6: 0.0858 | E6: 0.00403 | F6: =1 + E6 * (G6 - 20) -> 1.2821 | G6: 90 | H6: =G6-30 -> 60 | I6: =IFERROR(B6/H6,0) -> 6.5833333 | J6: TR_ATUAL | K6: =PROJ1!P3 -> 150 | M6: 75 | N6: 0.035 | P6: =20 -> 20 | Q6: =20 -> 20 | S6: QT_TR | T6: =K8 -> 0.029798369 | U6: pu | W6: =INDEX(CABOS[CONDUTORES],5) -> 240 Al - Arm | X6: =IF(ISNUMBER(FIND(" Cu",W6)),"CU",IF(ISNUMBER(FIND(" Al",W6)),"AL",IF(ISNUMBER(FIND(" AA",W6)),"AA","OUTRO"))) -> AL | Y6: =UPPER(SUBSTITUTE(SUBSTITUTE(SUBSTITUTE(SUBSTITUTE(W6," - ","_")," ","_"),"-","_"),".","")) -> 240_AL_ARM | AA6: 240 Al - Arm | AB6: =(SQRT(3)*((CABOS[[#This Row],[DIVISOR_R]]*COS(fator_potencia))+(SIN(fator_potencia)*CABOS[[#This Row],[Reatância]])))/1000 -> 0.0014635563 | AC6: =2*((CABOS[[#This Row],[DIVISOR_R]]*COS(fator_potencia))+(SIN(fator_potencia)*CABOS[[#This Row],[Reatância]]))/1000 -> 0.0016899693 | AD6: =CABOS[[#This Row],[(A)]]*AB6 -> 0.57810475 | AE6: =CABOS[[#This Row],[(A)]]*AC6 -> 0.66753787 | AF6: =AD6*40 -> 23.12419 | AG6: =AF6/220 -> 0.10510995
A7: 25 Al | B7: 90 | C7: 1.5693 | D7: 0.109 | E7: 0.00403 | F7: =1 + E7 * (G7 - 20) -> 1.2821 | G7: 90 | H7: =G7-30 -> 60 | I7: =IFERROR(B7/H7,0) -> 1.5 | J7: DEM_ATUAL | K7: =PROJ1!J9 -> 127.70729 | M7: 112.5 | N7: 0.035 | P7: =25 -> 25 | Q7: =25 -> 25 | S7: QT_MTTR | T7: =K10 -> 0.048098369 | U7: pu | W7: =INDEX(CABOS[CONDUTORES],6) -> 25 Al | X7: =IF(ISNUMBER(FIND(" Cu",W7)),"CU",IF(ISNUMBER(FIND(" Al",W7)),"AL",IF(ISNUMBER(FIND(" AA",W7)),"AA","OUTRO"))) -> AL | Y7: =UPPER(SUBSTITUTE(SUBSTITUTE(SUBSTITUTE(SUBSTITUTE(W7," - ","_")," ","_"),"-","_"),".","")) -> 25_AL | AA7: 25 Al | AB7: =(SQRT(3)*((CABOS[[#This Row],[DIVISOR_R]]*COS(fator_potencia))+(SIN(fator_potencia)*CABOS[[#This Row],[Reatância]])))/1000 -> 0.0014955265 | AC7: =2*((CABOS[[#This Row],[DIVISOR_R]]*COS(fator_potencia))+(SIN(fator_potencia)*CABOS[[#This Row],[Reatância]]))/1000 -> 0.0017268852 | AD7: =CABOS[[#This Row],[(A)]]*AB7 -> 0.13459738 | AE7: =CABOS[[#This Row],[(A)]]*AC7 -> 0.15541967 | AF7: =AD7*40 -> 5.3838952 | AG7: =AF7/220 -> 0.024472251
A8: 35 Cu | B8: 140 | C8: 0.6887 | D8: 0.1048 | E8: 0.00393 | F8: =1 + E8 * (G8 - 20) -> 1.2751 | G8: 90 | H8: =G8-30 -> 60 | I8: =IFERROR(B8/H8,0) -> 2.3333333 | J8: QT_TR | K8: =(DEM_ATUAL/TR_ATUAL)*VLOOKUP(TR_ATUAL,TRAFOS_Z[],2,0) -> 0.029798369 | M8: 150 | N8: 0.035 | P8: =32 -> 32 | Q8: =32 -> 32 | W8: =INDEX(CABOS[CONDUTORES],7) -> 35 Cu | X8: =IF(ISNUMBER(FIND(" Cu",W8)),"CU",IF(ISNUMBER(FIND(" Al",W8)),"AL",IF(ISNUMBER(FIND(" AA",W8)),"AA","OUTRO"))) -> CU | Y8: =UPPER(SUBSTITUTE(SUBSTITUTE(SUBSTITUTE(SUBSTITUTE(W8," - ","_")," ","_"),"-","_"),".","")) -> 35_CU | AA8: 35 Cu | AB8: =(SQRT(3)*((CABOS[[#This Row],[DIVISOR_R]]*COS(fator_potencia))+(SIN(fator_potencia)*CABOS[[#This Row],[Reatância]])))/1000 -> 0.0014823936 | AC8: =2*((CABOS[[#This Row],[DIVISOR_R]]*COS(fator_potencia))+(SIN(fator_potencia)*CABOS[[#This Row],[Reatância]]))/1000 -> 0.0017117207 | AD8: =CABOS[[#This Row],[(A)]]*AB8 -> 0.2075351 | AE8: =CABOS[[#This Row],[(A)]]*AC8 -> 0.23964089 | AF8: =AD8*40 -> 8.301404 | AG8: =AF8/220 -> 0.037733655
A9: 70 Cu | B9: 240 | C9: 0.3523 | D9: 0.1024 | E9: 0.00393 | F9: =1 + E9 * (G9 - 20) -> 1.2751 | G9: 90 | H9: =G9-30 -> 60 | I9: =IFERROR(B9/H9,0) -> 4 | M9: 225 | N9: 0.035 | P9: =40 -> 40 | Q9: =40 -> 40 | W9: =INDEX(CABOS[CONDUTORES],8) -> 70 Cu | X9: =IF(ISNUMBER(FIND(" Cu",W9)),"CU",IF(ISNUMBER(FIND(" Al",W9)),"AL",IF(ISNUMBER(FIND(" AA",W9)),"AA","OUTRO"))) -> CU | Y9: =UPPER(SUBSTITUTE(SUBSTITUTE(SUBSTITUTE(SUBSTITUTE(W9," - ","_")," ","_"),"-","_"),".","")) -> 70_CU | AA9: 70 Cu | AB9: =(SQRT(3)*((CABOS[[#This Row],[DIVISOR_R]]*COS(fator_potencia))+(SIN(fator_potencia)*CABOS[[#This Row],[Reatância]])))/1000 -> 0.0014790863 | AC9: =2*((CABOS[[#This Row],[DIVISOR_R]]*COS(fator_potencia))+(SIN(fator_potencia)*CABOS[[#This Row],[Reatância]]))/1000 -> 0.0017079018 | AD9: =CABOS[[#This Row],[(A)]]*AB9 -> 0.35498072 | AE9: =CABOS[[#This Row],[(A)]]*AC9 -> 0.40989643 | AF9: =AD9*40 -> 14.199229 | AG9: =AF9/220 -> 0.064541949
A10: 95 Al | B10: 225 | C10: 0.4195 | D10: 0.0958 | E10: 0.00403 | F10: =1 + E10 * (G10 - 20) -> 1.2821 | G10: 90 | H10: =G10-30 -> 60 | I10: =IFERROR(B10/H10,0) -> 3.75 | J10: QT_MTTR | K10: =QT_MT+QT_TR -> 0.048098369 | M10: 300 | N10: 0.035 | P10: =50 -> 50 | Q10: =50 -> 50 | W10: =INDEX(CABOS[CONDUTORES],9) -> 95 Al | X10: =IF(ISNUMBER(FIND(" Cu",W10)),"CU",IF(ISNUMBER(FIND(" Al",W10)),"AL",IF(ISNUMBER(FIND(" AA",W10)),"AA","OUTRO"))) -> AL | Y10: =UPPER(SUBSTITUTE(SUBSTITUTE(SUBSTITUTE(SUBSTITUTE(W10," - ","_")," ","_"),"-","_"),".","")) -> 95_AL | AA10: 95 Al | AB10: =(SQRT(3)*((CABOS[[#This Row],[DIVISOR_R]]*COS(fator_potencia))+(SIN(fator_potencia)*CABOS[[#This Row],[Reatância]])))/1000 -> 0.0014773366 | AC10: =2*((CABOS[[#This Row],[DIVISOR_R]]*COS(fator_potencia))+(SIN(fator_potencia)*CABOS[[#This Row],[Reatância]]))/1000 -> 0.0017058813 | AD10: =CABOS[[#This Row],[(A)]]*AB10 -> 0.33240072 | AE10: =CABOS[[#This Row],[(A)]]*AC10 -> 0.3838233 | AF10: =AD10*40 -> 13.296029 | AG10: =AF10/220 -> 0.060436495
A11: 120 Cu | B11: 340 | C11: 0.2023 | D11: 0.0971 | E11: 0.00393 | F11: =1 + E11 * (G11 - 20) -> 1.2751 | G11: 90 | H11: =G11-30 -> 60 | I11: =IFERROR(B11/H11,0) -> 5.6666667 | P11: =63 -> 63 | Q11: =63 -> 63 | W11: =INDEX(CABOS[CONDUTORES],10) -> 120 Cu | X11: =IF(ISNUMBER(FIND(" Cu",W11)),"CU",IF(ISNUMBER(FIND(" Al",W11)),"AL",IF(ISNUMBER(FIND(" AA",W11)),"AA","OUTRO"))) -> CU | Y11: =UPPER(SUBSTITUTE(SUBSTITUTE(SUBSTITUTE(SUBSTITUTE(W11," - ","_")," ","_"),"-","_"),".","")) -> 120_CU | AA11: 120 Cu | AB11: =(SQRT(3)*((CABOS[[#This Row],[DIVISOR_R]]*COS(fator_potencia))+(SIN(fator_potencia)*CABOS[[#This Row],[Reatância]])))/1000 -> 0.0014717828 | AC11: =2*((CABOS[[#This Row],[DIVISOR_R]]*COS(fator_potencia))+(SIN(fator_potencia)*CABOS[[#This Row],[Reatância]]))/1000 -> 0.0016994684 | AD11: =CABOS[[#This Row],[(A)]]*AB11 -> 0.50040615 | AE11: =CABOS[[#This Row],[(A)]]*AC11 -> 0.57781926 | AF11: =AD11*40 -> 20.016246 | AG11: =AF11/220 -> 0.090982937
A12: 240 Al | B12: 476 | C12: 0.1663 | D12: 0.0897 | E12: 0.00403 | F12: =1 + E12 * (G12 - 20) -> 1.2821 | G12: 90 | H12: =G12-30 -> 60 | I12: =IFERROR(B12/H12,0) -> 7.9333333 | P12: =80 -> 80 | Q12: =80 -> 80 | W12: =INDEX(CABOS[CONDUTORES],11) -> 240 Al | X12: =IF(ISNUMBER(FIND(" Cu",W12)),"CU",IF(ISNUMBER(FIND(" Al",W12)),"AL",IF(ISNUMBER(FIND(" AA",W12)),"AA","OUTRO"))) -> AL | Y12: =UPPER(SUBSTITUTE(SUBSTITUTE(SUBSTITUTE(SUBSTITUTE(W12," - ","_")," ","_"),"-","_"),".","")) -> 240_AL | AA12: 240 Al | AB12: =(SQRT(3)*((CABOS[[#This Row],[DIVISOR_R]]*COS(fator_potencia))+(SIN(fator_potencia)*CABOS[[#This Row],[Reatância]])))/1000 -> 0.0014689306 | AC12: =2*((CABOS[[#This Row],[DIVISOR_R]]*COS(fator_potencia))+(SIN(fator_potencia)*CABOS[[#This Row],[Reatância]]))/1000 -> 0.001696175 | AD12: =CABOS[[#This Row],[(A)]]*AB12 -> 0.69921097 | AE12: =CABOS[[#This Row],[(A)]]*AC12 -> 0.80737929 | AF12: =AD12*40 -> 27.968439 | AG12: =AF12/220 -> 0.12712927
A13: 240 Cu | B13: 430 | C13: 0.1035 | D13: 0.0897 | E13: 0.00393 | F13: =1 + E13 * (G13 - 20) -> 1.2751 | G13: 90 | H13: =G13-30 -> 60 | I13: =IFERROR(B13/H13,0) -> 7.1666667 | M13: 220 | P13: =100 -> 100 | Q13: =100 -> 100 | W13: =INDEX(CABOS[CONDUTORES],12) -> 240 Cu | X13: =IF(ISNUMBER(FIND(" Cu",W13)),"CU",IF(ISNUMBER(FIND(" Al",W13)),"AL",IF(ISNUMBER(FIND(" AA",W13)),"AA","OUTRO"))) -> CU | Y13: =UPPER(SUBSTITUTE(SUBSTITUTE(SUBSTITUTE(SUBSTITUTE(W13," - ","_")," ","_"),"-","_"),".","")) -> 240_CU | AA13: 240 Cu | AB13: =(SQRT(3)*((CABOS[[#This Row],[DIVISOR_R]]*COS(fator_potencia))+(SIN(fator_potencia)*CABOS[[#This Row],[Reatância]])))/1000 -> 0.0014615854 | AC13: =2*((CABOS[[#This Row],[DIVISOR_R]]*COS(fator_potencia))+(SIN(fator_potencia)*CABOS[[#This Row],[Reatância]]))/1000 -> 0.0016876935 | AD13: =CABOS[[#This Row],[(A)]]*AB13 -> 0.62848174 | AE13: =CABOS[[#This Row],[(A)]]*AC13 -> 0.7257082 | AF13: =AD13*40 -> 25.13927 | AG13: =AF13/220 -> 0.11426941
A14: 500 Cu | B14: 700 | C14: 0.0568 | D14: 0.0849 | E14: 0.00393 | F14: =1 + E14 * (G14 - 20) -> 1.2751 | G14: 90 | H14: =G14-30 -> 60 | I14: =IFERROR(B14/H14,0) -> 11.666667 | M14: =T_LINHA_TRF/SQRT(3) -> 127.01706 | P14: =125 -> 125 | Q14: =125 -> 125 | W14: =INDEX(CABOS[CONDUTORES],13) -> 500 Cu | X14: =IF(ISNUMBER(FIND(" Cu",W14)),"CU",IF(ISNUMBER(FIND(" Al",W14)),"AL",IF(ISNUMBER(FIND(" AA",W14)),"AA","OUTRO"))) -> CU | Y14: =UPPER(SUBSTITUTE(SUBSTITUTE(SUBSTITUTE(SUBSTITUTE(W14," - ","_")," ","_"),"-","_"),".","")) -> 500_CU | AA14: 500 Cu | AB14: =(SQRT(3)*((CABOS[[#This Row],[DIVISOR_R]]*COS(fator_potencia))+(SIN(fator_potencia)*CABOS[[#This Row],[Reatância]])))/1000 -> 0.0014549709 | AC14: =2*((CABOS[[#This Row],[DIVISOR_R]]*COS(fator_potencia))+(SIN(fator_potencia)*CABOS[[#This Row],[Reatância]]))/1000 -> 0.0016800557 | AD14: =CABOS[[#This Row],[(A)]]*AB14 -> 1.0184797 | AE14: =CABOS[[#This Row],[(A)]]*AC14 -> 1.176039 | AF14: =AD14*40 -> 40.739186 | AG14: =AF14/220 -> 0.18517812
A15: 10 Cu_CONC_bi | B15: 63 | C15: 2.3801017 | D15: 0.101 | E15: 0.00393 | F15: =1 + E15 * (G15 - 20) -> 1.2751 | G15: 90 | H15: =G15-30 -> 60 | I15: =IFERROR(B15/H15,0) -> 1.05 | J15: TR_PROJ1 | K15: ='GERAL PROJ'!O3 -> 112.5 | P15: =160 -> 160 | Q15: =160 -> 160 | W15: =INDEX(CABOS[CONDUTORES],14) -> 10 Cu_CONC_bi | X15: =IF(ISNUMBER(FIND(" Cu",W15)),"CU",IF(ISNUMBER(FIND(" Al",W15)),"AL",IF(ISNUMBER(FIND(" AA",W15)),"AA","OUTRO"))) -> CU | Y15: =UPPER(SUBSTITUTE(SUBSTITUTE(SUBSTITUTE(SUBSTITUTE(W15," - ","_")," ","_"),"-","_"),".","")) -> 10_CU_CONC_BI | AA15: 10 Cu_CONC_bi | AB15: =(SQRT(3)*((CABOS[[#This Row],[DIVISOR_R]]*COS(fator_potencia))+(SIN(fator_potencia)*CABOS[[#This Row],[Reatância]])))/1000 -> 0.0014771571 | AC15: =2*((CABOS[[#This Row],[DIVISOR_R]]*COS(fator_potencia))+(SIN(fator_potencia)*CABOS[[#This Row],[Reatância]]))/1000 -> 0.0017056741 | AD15: =CABOS[[#This Row],[(A)]]*AB15 -> 0.093060897 | AE15: =CABOS[[#This Row],[(A)]]*AC15 -> 0.10745747 | AF15: =AD15*40 -> 3.7224359 | AG15: =AF15/220 -> 0.016920163
A16: 10 Cu_CONC_Tri | B16: 63 | C16: 2.3801017 | D16: 0.101 | E16: 0.00393 | F16: =1 + E16 * (G16 - 20) -> 1.2751 | G16: 90 | H16: =G16-30 -> 60 | I16: =IFERROR(B16/H16,0) -> 1.05 | J16: DEM_PROJ1 | K16: =RAMAL!AC24 | P16: =200 -> 200 | Q16: =200 -> 200 | W16: =INDEX(CABOS[CONDUTORES],15) -> 10 Cu_CONC_Tri | X16: =IF(ISNUMBER(FIND(" Cu",W16)),"CU",IF(ISNUMBER(FIND(" Al",W16)),"AL",IF(ISNUMBER(FIND(" AA",W16)),"AA","OUTRO"))) -> CU | Y16: =UPPER(SUBSTITUTE(SUBSTITUTE(SUBSTITUTE(SUBSTITUTE(W16," - ","_")," ","_"),"-","_"),".","")) -> 10_CU_CONC_TRI | AA16: 10 Cu_CONC_Tri | AB16: =(SQRT(3)*((CABOS[[#This Row],[DIVISOR_R]]*COS(fator_potencia))+(SIN(fator_potencia)*CABOS[[#This Row],[Reatância]])))/1000 -> 0.0014771571 | AC16: =2*((CABOS[[#This Row],[DIVISOR_R]]*COS(fator_potencia))+(SIN(fator_potencia)*CABOS[[#This Row],[Reatância]]))/1000 -> 0.0017056741 | AD16: =CABOS[[#This Row],[(A)]]*AB16 -> 0.093060897 | AE16: =CABOS[[#This Row],[(A)]]*AC16 -> 0.10745747 | AF16: =AD16*40 -> 3.7224359 | AG16: =AF16/220 -> 0.016920163
A17: 16 Al_CONC_bi | B17: 63 | C17: 2.4977872 | D17: 0.085 | E17: 0.00403 | F17: =1 + E17 * (G17 - 20) -> 1.2821 | G17: 90 | H17: =G17-30 -> 60 | I17: =IFERROR(B17/H17,0) -> 1.05 | J17: QT_TR | K17: =(K16/K15)*VLOOKUP(K15,TRAFOS_Z[],2,0) -> #VALUE! | P17: =250 -> 250 | Q17: =250 -> 250 | W17: =INDEX(CABOS[CONDUTORES],16) -> 16 Al_CONC_bi | X17: =IF(ISNUMBER(FIND(" Cu",W17)),"CU",IF(ISNUMBER(FIND(" Al",W17)),"AL",IF(ISNUMBER(FIND(" AA",W17)),"AA","OUTRO"))) -> AL | Y17: =UPPER(SUBSTITUTE(SUBSTITUTE(SUBSTITUTE(SUBSTITUTE(W17," - ","_")," ","_"),"-","_"),".","")) -> 16_AL_CONC_BI | AA17: 16 Al_CONC_bi | AB17: =(SQRT(3)*((CABOS[[#This Row],[DIVISOR_R]]*COS(fator_potencia))+(SIN(fator_potencia)*CABOS[[#This Row],[Reatância]])))/1000 -> 0.0014624539 | AC17: =2*((CABOS[[#This Row],[DIVISOR_R]]*COS(fator_potencia))+(SIN(fator_potencia)*CABOS[[#This Row],[Reatância]]))/1000 -> 0.0016886963 | AD17: =CABOS[[#This Row],[(A)]]*AB17 -> 0.092134597 | AE17: =CABOS[[#This Row],[(A)]]*AC17 -> 0.10638787 | AF17: =AD17*40 -> 3.6853839 | AG17: =AF17/220 -> 0.016751745
A18: 16 Al_CONC_Tri | B18: 63 | C18: 2.4977872 | D18: 0.85 | E18: 0.00403 | F18: =1 + E18 * (G18 - 20) -> 1.2821 | G18: 90 | H18: =G18-30 -> 60 | I18: =IFERROR(B18/H18,0) -> 1.05 | P18: =315 -> 315 | Q18: =315 -> 315 | W18: =INDEX(CABOS[CONDUTORES],17) -> 16 Al_CONC_Tri | X18: =IF(ISNUMBER(FIND(" Cu",W18)),"CU",IF(ISNUMBER(FIND(" Al",W18)),"AL",IF(ISNUMBER(FIND(" AA",W18)),"AA","OUTRO"))) -> AL | Y18: =UPPER(SUBSTITUTE(SUBSTITUTE(SUBSTITUTE(SUBSTITUTE(W18," - ","_")," ","_"),"-","_"),".","")) -> 16_AL_CONC_TRI | AA18: 16 Al_CONC_Tri | AB18: =(SQRT(3)*((CABOS[[#This Row],[DIVISOR_R]]*COS(fator_potencia))+(SIN(fator_potencia)*CABOS[[#This Row],[Reatância]])))/1000 -> 0.0025166411 | AC18: =2*((CABOS[[#This Row],[DIVISOR_R]]*COS(fator_potencia))+(SIN(fator_potencia)*CABOS[[#This Row],[Reatância]]))/1000 -> 0.0029059668 | AD18: =CABOS[[#This Row],[(A)]]*AB18 -> 0.15854839 | AE18: =CABOS[[#This Row],[(A)]]*AC18 -> 0.18307591 | AF18: =AD18*40 -> 6.3419355 | AG18: =AF18/220 -> 0.02882698
A19: 13 Al - DX | B19: 63 | C19: 2.6655 | D19: 0.1022 | E19: 0.00403 | F19: =1 + E19 * (G19 - 20) -> 1.2015 | G19: 70 | H19: =G19-30 -> 40 | I19: =IFERROR(B19/H19,0) -> 1.575 | J19: QT_MTTR2 | K19: =QT_MT+K17 -> #VALUE! | P19: =400 -> 400 | Q19: =400 -> 400 | W19: =INDEX(CABOS[CONDUTORES],18) -> 13 Al - DX | X19: =IF(ISNUMBER(FIND(" Cu",W19)),"CU",IF(ISNUMBER(FIND(" Al",W19)),"AL",IF(ISNUMBER(FIND(" AA",W19)),"AA","OUTRO"))) -> AL | Y19: =UPPER(SUBSTITUTE(SUBSTITUTE(SUBSTITUTE(SUBSTITUTE(W19," - ","_")," ","_"),"-","_"),".","")) -> 13_AL_DX | AA19: 13 Al - DX | AB19: =(SQRT(3)*((CABOS[[#This Row],[DIVISOR_R]]*COS(fator_potencia))+(SIN(fator_potencia)*CABOS[[#This Row],[Reatância]])))/1000 -> 0.0014015814 | AC19: =2*((CABOS[[#This Row],[DIVISOR_R]]*COS(fator_potencia))+(SIN(fator_potencia)*CABOS[[#This Row],[Reatância]]))/1000 -> 0.0016184068 | AD19: =CABOS[[#This Row],[(A)]]*AB19 -> 0.088299629 | AE19: =CABOS[[#This Row],[(A)]]*AC19 -> 0.10195963 | AF19: =AD19*40 -> 3.5319852 | AG19: =AF19/220 -> 0.016054478
A20: 13 Al - TX | B20: 63 | C20: 2.6655 | D20: 0.1158 | E20: 0.00403 | F20: =1 + E20 * (G20 - 20) -> 1.2015 | G20: 70 | H20: =G20-30 -> 40 | I20: =IFERROR(B20/H20,0) -> 1.575 | P20: =500 -> 500 | Q20: =500 -> 500 | W20: =INDEX(CABOS[CONDUTORES],19) -> 13 Al - TX | X20: =IF(ISNUMBER(FIND(" Cu",W20)),"CU",IF(ISNUMBER(FIND(" Al",W20)),"AL",IF(ISNUMBER(FIND(" AA",W20)),"AA","OUTRO"))) -> AL | Y20: =UPPER(SUBSTITUTE(SUBSTITUTE(SUBSTITUTE(SUBSTITUTE(W20," - ","_")," ","_"),"-","_"),".","")) -> 13_AL_TX | AA20: 13 Al - TX | AB20: =(SQRT(3)*((CABOS[[#This Row],[DIVISOR_R]]*COS(fator_potencia))+(SIN(fator_potencia)*CABOS[[#This Row],[Reatância]])))/1000 -> 0.0014203225 | AC20: =2*((CABOS[[#This Row],[DIVISOR_R]]*COS(fator_potencia))+(SIN(fator_potencia)*CABOS[[#This Row],[Reatância]]))/1000 -> 0.0016400472 | AD20: =CABOS[[#This Row],[(A)]]*AB20 -> 0.089480318 | AE20: =CABOS[[#This Row],[(A)]]*AC20 -> 0.10332297 | AF20: =AD20*40 -> 3.5792127 | AG20: =AF20/220 -> 0.016269149
A21: 13 Al - QX | B21: 63 | C21: 2.6655 | D21: 0.1384 | E21: 0.00403 | F21: =1 + E21 * (G21 - 20) -> 1.2015 | G21: 70 | H21: =G21-30 -> 40 | I21: =IFERROR(B21/H21,0) -> 1.575 | P21: =630 -> 630 | Q21: =630 -> 630 | W21: =INDEX(CABOS[CONDUTORES],20) -> 13 Al - QX | X21: =IF(ISNUMBER(FIND(" Cu",W21)),"CU",IF(ISNUMBER(FIND(" Al",W21)),"AL",IF(ISNUMBER(FIND(" AA",W21)),"AA","OUTRO"))) -> AL | Y21: =UPPER(SUBSTITUTE(SUBSTITUTE(SUBSTITUTE(SUBSTITUTE(W21," - ","_")," ","_"),"-","_"),".","")) -> 13_AL_QX | AA21: 13 Al - QX | AB21: =(SQRT(3)*((CABOS[[#This Row],[DIVISOR_R]]*COS(fator_potencia))+(SIN(fator_potencia)*CABOS[[#This Row],[Reatância]])))/1000 -> 0.0014514658 | AC21: =2*((CABOS[[#This Row],[DIVISOR_R]]*COS(fator_potencia))+(SIN(fator_potencia)*CABOS[[#This Row],[Reatância]]))/1000 -> 0.0016760084 | AD21: =CABOS[[#This Row],[(A)]]*AB21 -> 0.091442347 | AE21: =CABOS[[#This Row],[(A)]]*AC21 -> 0.10558853 | AF21: =AD21*40 -> 3.6576939 | AG21: =AF21/220 -> 0.016625881
A22: 21 Al - QX | B22: 63 | C22: 1.677 | D22: 0.135 | E22: 0.00403 | F22: =1 + E22 * (G22 - 20) -> 1.2015 | G22: 70 | H22: =G22-30 -> 40 | I22: =IFERROR(B22/H22,0) -> 1.575 | J22: TR_PROJ2 | K22: ='GERAL PROJ2'!O3 -> 112.5 | W22: =INDEX(CABOS[CONDUTORES],21) -> 21 Al - QX | X22: =IF(ISNUMBER(FIND(" Cu",W22)),"CU",IF(ISNUMBER(FIND(" Al",W22)),"AL",IF(ISNUMBER(FIND(" AA",W22)),"AA","OUTRO"))) -> AL | Y22: =UPPER(SUBSTITUTE(SUBSTITUTE(SUBSTITUTE(SUBSTITUTE(W22," - ","_")," ","_"),"-","_"),".","")) -> 21_AL_QX | AA22: 21 Al - QX | AB22: =(SQRT(3)*((CABOS[[#This Row],[DIVISOR_R]]*COS(fator_potencia))+(SIN(fator_potencia)*CABOS[[#This Row],[Reatância]])))/1000 -> 0.0014467805 | AC22: =2*((CABOS[[#This Row],[DIVISOR_R]]*COS(fator_potencia))+(SIN(fator_potencia)*CABOS[[#This Row],[Reatância]]))/1000 -> 0.0016705983 | AD22: =CABOS[[#This Row],[(A)]]*AB22 -> 0.091147174 | AE22: =CABOS[[#This Row],[(A)]]*AC22 -> 0.10524769 | AF22: =AD22*40 -> 3.645887 | AG22: =AF22/220 -> 0.016572214
A23: 53 Al - QX | B23: 63 | C23: 0.6641 | D23: 0.1311 | E23: 0.00403 | F23: =1 + E23 * (G23 - 20) -> 1.2015 | G23: 70 | H23: =G23-30 -> 40 | I23: =IFERROR(B23/H23,0) -> 1.575 | J23: DEM_PROJ2 | K23: =RAMAL!AE24 | W23: =INDEX(CABOS[CONDUTORES],22) -> 53 Al - QX | X23: =IF(ISNUMBER(FIND(" Cu",W23)),"CU",IF(ISNUMBER(FIND(" Al",W23)),"AL",IF(ISNUMBER(FIND(" AA",W23)),"AA","OUTRO"))) -> AL | Y23: =UPPER(SUBSTITUTE(SUBSTITUTE(SUBSTITUTE(SUBSTITUTE(W23," - ","_")," ","_"),"-","_"),".","")) -> 53_AL_QX | AA23: 53 Al - QX | AB23: =(SQRT(3)*((CABOS[[#This Row],[DIVISOR_R]]*COS(fator_potencia))+(SIN(fator_potencia)*CABOS[[#This Row],[Reatância]])))/1000 -> 0.0014414063 | AC23: =2*((CABOS[[#This Row],[DIVISOR_R]]*COS(fator_potencia))+(SIN(fator_potencia)*CABOS[[#This Row],[Reatância]]))/1000 -> 0.0016643926 | AD23: =CABOS[[#This Row],[(A)]]*AB23 -> 0.090808594 | AE23: =CABOS[[#This Row],[(A)]]*AC23 -> 0.10485673 | AF23: =AD23*40 -> 3.6323438 | AG23: =AF23/220 -> 0.016510653
A24: 53 AA | B24: 163 | C24: 0.6641 | D24: 0.1311 | E24: 0.00403 | F24: =1 + E24 * (G24 - 20) -> 1.2821 | G24: 90 | H24: =G24-30 -> 60 | I24: =IFERROR(B24/H24,0) -> 2.7166667 | J24: QT_TR | K24: =(K23/K22)*VLOOKUP(K22,TRAFOS_Z[],2,0) -> #VALUE! | W24: =INDEX(CABOS[CONDUTORES],23) -> 53 AA | X24: =IF(ISNUMBER(FIND(" Cu",W24)),"CU",IF(ISNUMBER(FIND(" Al",W24)),"AL",IF(ISNUMBER(FIND(" AA",W24)),"AA","OUTRO"))) -> AA | Y24: =UPPER(SUBSTITUTE(SUBSTITUTE(SUBSTITUTE(SUBSTITUTE(W24," - ","_")," ","_"),"-","_"),".","")) -> 53_AA | AA24: 53 AA | AB24: =(SQRT(3)*((CABOS[[#This Row],[DIVISOR_R]]*COS(fator_potencia))+(SIN(fator_potencia)*CABOS[[#This Row],[Reatância]])))/1000 -> 0.0015259807 | AC24: =2*((CABOS[[#This Row],[DIVISOR_R]]*COS(fator_potencia))+(SIN(fator_potencia)*CABOS[[#This Row],[Reatância]]))/1000 -> 0.0017620508 | AD24: =CABOS[[#This Row],[(A)]]*AB24 -> 0.24873486 | AE24: =CABOS[[#This Row],[(A)]]*AC24 -> 0.28721428 | AF24: =AD24*40 -> 9.9493945 | AG24: =AF24/220 -> 0.04522452
A25: 70 Al - MX | B25: 202 | C25: 0.5697 | D25: 0.126 | E25: 0.00403 | F25: =1 + E25 * (G25 - 20) -> 1.2821 | G25: 90 | H25: =G25-30 -> 60 | I25: =IFERROR(B25/H25,0) -> 3.3666667 | W25: =INDEX(CABOS[CONDUTORES],24) -> 70 Al - MX | X25: =IF(ISNUMBER(FIND(" Cu",W25)),"CU",IF(ISNUMBER(FIND(" Al",W25)),"AL",IF(ISNUMBER(FIND(" AA",W25)),"AA","OUTRO"))) -> AL | Y25: =UPPER(SUBSTITUTE(SUBSTITUTE(SUBSTITUTE(SUBSTITUTE(W25," - ","_")," ","_"),"-","_"),".","")) -> 70_AL_MX | AA25: 70 Al - MX | AB25: =(SQRT(3)*((CABOS[[#This Row],[DIVISOR_R]]*COS(fator_potencia))+(SIN(fator_potencia)*CABOS[[#This Row],[Reatância]])))/1000 -> 0.0015189528 | AC25: =2*((CABOS[[#This Row],[DIVISOR_R]]*COS(fator_potencia))+(SIN(fator_potencia)*CABOS[[#This Row],[Reatância]]))/1000 -> 0.0017539357 | AD25: =CABOS[[#This Row],[(A)]]*AB25 -> 0.30682847 | AE25: =CABOS[[#This Row],[(A)]]*AC25 -> 0.354295 | AF25: =AD25*40 -> 12.273139 | AG25: =AF25/220 -> 0.055786995
A26: 185 Al - MX | B26: 355 | C26: 0.2149 | D26: 0.1178 | E26: 0.00403 | F26: =1 + E26 * (G26 - 20) -> 1.2821 | G26: 90 | H26: =G26-30 -> 60 | I26: =IFERROR(B26/H26,0) -> 5.9166667 | J26: QT_MTTR3 | K26: =QT_MT+K24 -> #VALUE! | W26: =INDEX(CABOS[CONDUTORES],25) -> 185 Al - MX | X26: =IF(ISNUMBER(FIND(" Cu",W26)),"CU",IF(ISNUMBER(FIND(" Al",W26)),"AL",IF(ISNUMBER(FIND(" AA",W26)),"AA","OUTRO"))) -> AL | Y26: =UPPER(SUBSTITUTE(SUBSTITUTE(SUBSTITUTE(SUBSTITUTE(W26," - ","_")," ","_"),"-","_"),".","")) -> 185_AL_MX | AA26: 185 Al - MX | AB26: =(SQRT(3)*((CABOS[[#This Row],[DIVISOR_R]]*COS(fator_potencia))+(SIN(fator_potencia)*CABOS[[#This Row],[Reatância]])))/1000 -> 0.001507653 | AC26: =2*((CABOS[[#This Row],[DIVISOR_R]]*COS(fator_potencia))+(SIN(fator_potencia)*CABOS[[#This Row],[Reatância]]))/1000 -> 0.0017408878 | AD26: =CABOS[[#This Row],[(A)]]*AB26 -> 0.53521683 | AE26: =CABOS[[#This Row],[(A)]]*AC26 -> 0.61801516 | AF26: =AD26*40 -> 21.408673 | AG26: =AF26/220 -> 0.097312151
A27: 240 Al - MX | B27: 473 | C27: 0.163 | D27: 0.0903 | E27: 0.00403 | F27: =1 + E27 * (G27 - 20) -> 1.2821 | G27: 90 | H27: =G27-30 -> 60 | I27: =IFERROR(B27/H27,0) -> 7.8833333 | P27: km construido | Q27: cusot final | AA27: 240 Al - MX | AB27: =(SQRT(3)*((CABOS[[#This Row],[DIVISOR_R]]*COS(fator_potencia))+(SIN(fator_potencia)*CABOS[[#This Row],[Reatância]])))/1000 -> 0.0014697574 | AC27: =2*((CABOS[[#This Row],[DIVISOR_R]]*COS(fator_potencia))+(SIN(fator_potencia)*CABOS[[#This Row],[Reatância]]))/1000 -> 0.0016971297 | AD27: =CABOS[[#This Row],[(A)]]*AB27 -> 0.69519527 | AE27: =CABOS[[#This Row],[(A)]]*AC27 -> 0.80274235 | AF27: =AD27*40 -> 27.807811 | AG27: =AF27/220 -> 0.12639914
A28: 6 AWG | B28: 65 | C28: 1.3 | D28: 0.09 | E28: 0.00403 | F28: =1 + E28 * (G28 - 20) -> 1.2821 | G28: =IF(OR(A28="13 Al - DX",A28="13 Al - TX",A28="13 Al - QX",A28="21 Al - QX",A28="53 Al - QX"),70,90) -> 90 | H28: =G28-30 -> 60 | I28: =IFERROR(B28/H28,0) -> 1.0833333 | N28: Rede Com Estrutura | O28: BT | S28: CUSTO | AA28: 6 AWG | AB28: =(SQRT(3)*((CABOS[[#This Row],[DIVISOR_R]]*COS(fator_potencia))+(SIN(fator_potencia)*CABOS[[#This Row],[Reatância]])))/1000 -> 0.001469344 | AC28: =2*((CABOS[[#This Row],[DIVISOR_R]]*COS(fator_potencia))+(SIN(fator_potencia)*CABOS[[#This Row],[Reatância]]))/1000 -> 0.0016966523 | AD28: =CABOS[[#This Row],[(A)]]*AB28 -> 0.095507362 | AE28: =CABOS[[#This Row],[(A)]]*AC28 -> 0.1102824 | AF28: =AD28*40 -> 3.8202945 | AG28: =AF28/220 -> 0.017364975
A29: 2 AWG | B29: 100 | C29: 0.82 | D29: 0.085 | E29: 0.00403 | F29: =1 + E29 * (G29 - 20) -> 1.2821 | G29: =IF(OR(A29="13 Al - DX",A29="13 Al - TX",A29="13 Al - QX",A29="21 Al - QX",A29="53 Al - QX"),70,90) -> 90 | H29: =G29-30 -> 60 | I29: =IFERROR(B29/H29,0) -> 1.6666667 | N29: Cabo 53 mm² CA – Nu e PVC | O29: 56371.129 | Q29: =P29*O29 -> 0 | S29: =SUM(Q29:Q58) -> 39745.57 | AA29: 2 AWG | AB29: =(SQRT(3)*((CABOS[[#This Row],[DIVISOR_R]]*COS(fator_potencia))+(SIN(fator_potencia)*CABOS[[#This Row],[Reatância]])))/1000 -> 0.0014624539 | AC29: =2*((CABOS[[#This Row],[DIVISOR_R]]*COS(fator_potencia))+(SIN(fator_potencia)*CABOS[[#This Row],[Reatância]]))/1000 -> 0.0016886963 | AD29: =CABOS[[#This Row],[(A)]]*AB29 -> 0.14624539 | AE29: =CABOS[[#This Row],[(A)]]*AC29 -> 0.16886963 | AF29: =AD29*40 -> 5.8498157 | AG29: =AF29/220 -> 0.026590071
A30: 1/0 AWG | B30: 150 | C30: 0.52 | D30: 0.08 | E30: 0.00403 | F30: =1 + E30 * (G30 - 20) -> 1.2821 | G30: =IF(OR(A30="13 Al - DX",A30="13 Al - TX",A30="13 Al - QX",A30="21 Al - QX",A30="53 Al - QX"),70,90) -> 90 | H30: =G30-30 -> 60 | I30: =IFERROR(B30/H30,0) -> 2.5 | N30: Cabo 201 mm² CA - Nu e PVC | O30: 110481.13 | Q30: =P30*O30 -> 0 | AA30: 1/0 AWG | AB30: =(SQRT(3)*((CABOS[[#This Row],[DIVISOR_R]]*COS(fator_potencia))+(SIN(fator_potencia)*CABOS[[#This Row],[Reatância]])))/1000 -> 0.0014555638 | AC30: =2*((CABOS[[#This Row],[DIVISOR_R]]*COS(fator_potencia))+(SIN(fator_potencia)*CABOS[[#This Row],[Reatância]]))/1000 -> 0.0016807403 | AD30: =CABOS[[#This Row],[(A)]]*AB30 -> 0.21833457 | AE30: =CABOS[[#This Row],[(A)]]*AC30 -> 0.25211105 | AF30: =AD30*40 -> 8.7333828 | AG30: =AF30/220 -> 0.039697195
A31: 3/0 AWG | B31: 200 | C31: 0.33 | D31: 0.078 | E31: 0.00403 | F31: =1 + E31 * (G31 - 20) -> 1.2821 | G31: =IF(OR(A31="13 Al - DX",A31="13 Al - TX",A31="13 Al - QX",A31="21 Al - QX",A31="53 Al - QX"),70,90) -> 90 | H31: =G31-30 -> 60 | I31: =IFERROR(B31/H31,0) -> 3.3333333 | N31: Cabo 70 mm² CA MMX | O31: 68591.91 | Q31: =P31*O31 -> 0 | AA31: 3/0 AWG | AB31: =(SQRT(3)*((CABOS[[#This Row],[DIVISOR_R]]*COS(fator_potencia))+(SIN(fator_potencia)*CABOS[[#This Row],[Reatância]])))/1000 -> 0.0014528078 | AC31: =2*((CABOS[[#This Row],[DIVISOR_R]]*COS(fator_potencia))+(SIN(fator_potencia)*CABOS[[#This Row],[Reatância]]))/1000 -> 0.0016775579 | AD31: =CABOS[[#This Row],[(A)]]*AB31 -> 0.29056155 | AE31: =CABOS[[#This Row],[(A)]]*AC31 -> 0.33551158 | AF31: =AD31*40 -> 11.622462 | AG31: =AF31/220 -> 0.052829373
A32: 4/0 AWG | B32: 230 | C32: 0.26 | D32: 0.075 | E32: 0.00403 | F32: =1 + E32 * (G32 - 20) -> 1.2821 | G32: =IF(OR(A32="13 Al - DX",A32="13 Al - TX",A32="13 Al - QX",A32="21 Al - QX",A32="53 Al - QX"),70,90) -> 90 | H32: =G32-30 -> 60 | I32: =IFERROR(B32/H32,0) -> 3.8333333 | N32: Cabo 185 mm² CA MMX | O32: 94961.91 | Q32: =P32*O32 -> 0 | AA32: 4/0 AWG | AB32: =(SQRT(3)*((CABOS[[#This Row],[DIVISOR_R]]*COS(fator_potencia))+(SIN(fator_potencia)*CABOS[[#This Row],[Reatância]])))/1000 -> 0.0014486737 | AC32: =2*((CABOS[[#This Row],[DIVISOR_R]]*COS(fator_potencia))+(SIN(fator_potencia)*CABOS[[#This Row],[Reatância]]))/1000 -> 0.0016727843 | AD32: =CABOS[[#This Row],[(A)]]*AB32 -> 0.33319495 | AE32: =CABOS[[#This Row],[(A)]]*AC32 -> 0.38474039 | AF32: =AD32*40 -> 13.327798 | AG32: =AF32/220 -> 0.0605809
N33: Cabo 240 mm² CA MMX | O33: 110011.91 | Q33: =P33*O33 -> 0
A35: Área (m²) | B35: kVA | C35: QTD Clientes | D35: Fator por área | E35: Fator Diversificação | F35: Demanda (KVA) | N35: Rede Cabo Armado | Q35: =P35*O35 -> 0
A36: 20 | B36: 1.62 | C36: 1 | D36: =RAMAL!AB35 -> 1.88 | E36: 3.88 | F36: =D36*E36 -> 7.2944 | N36: Cabo armado 3X1X50 mm²+35 mm² | O36: 102973.3 | Q36: =P36*O36 -> 0
A37: 21 | B37: 1.62 | C37: 2 | D37: =D36 -> 1.88 | E37: 3.88 | F37: =D37*E37 -> 7.2944 | N37: Cabo armado 3X1X95 mm²+50 mm² | O37: 122163.3 | Q37: =P37*O37 -> 0
A38: 22 | B38: 1.62 | C38: 3 | D38: =D37 -> 1.88 | E38: 3.88 | F38: =D38*E38 -> 7.2944 | N38: Cabo armado 3X1X240 mm²+120 mm² | O38: 163793.3 | Q38: =P38*O38 -> 0
A39: 23 | B39: 1.62 | C39: 4 | D39: =D38 -> 1.88 | E39: 3.88 | F39: =D39*E39 -> 7.2944 | O39: TRAFO
A40: 24 | B40: 1.62 | C40: 5 | D40: =D39 -> 1.88 | E40: 4.84 | F40: =D40*E40 -> 9.0992 | N40: Trafo Aéreo 45 kVA – Trifásico – 25,6 kV – Convencional ( Unidade ) | O40: 15780.16 | Q40: =P40*O40 -> 0
A41: 25 | B41: 1.62 | C41: 6 | D41: =D40 -> 1.88 | E41: 5.8 | F41: =D41*E41 -> 10.904 | N41: Trafo Aéreo 15 kVA – Trifásico – 13,8 kV – Convencional ( Unidade ) | O41: 6896.47 | Q41: =P41*O41 -> 0
...

Sheet COORDENADAS
B2: PONTO | C2: X / LAT / E | D2: Y / LON / N | F2: KVA CLAN | G2: DIST ENTRE COORDE | I2: POSTE | J2: X | K2: Y | L2: Z | Q2: X | R2: Y
B3: 1 | F3: =IF(Tabela13[[#This Row],[X / LAT / E]]="","",VLOOKUP(Tabela13[[#This Row],[PONTO]],RAMAIS_ATUAL,IF(PROJ1!$J$2="SIM",25,23),0)) | G3: =IFERROR(SQRT((D4-Tabela13[[#This Row],[Y / LON / N]])^2+(C4-Tabela13[[#This Row],[X / LAT / E]])^2),"") -> 0 | I3: 1 | M3: O | O3: POSTE A | P3: 25 | Q3: =VLOOKUP(P3,Tabela13[],2,0) -> 0 | R3: =VLOOKUP(P3,Tabela13[],3,0) -> 0
B4: 2 | F4: =IF(Tabela13[[#This Row],[X / LAT / E]]="","",VLOOKUP(Tabela13[[#This Row],[PONTO]],RAMAIS_ATUAL,IF(PROJ1!$J$2="SIM",25,23),0)) | G4: =SQRT((D5-Tabela13[[#This Row],[Y / LON / N]])^2+(C5-Tabela13[[#This Row],[X / LAT / E]])^2) -> 0 | I4: 2 | M4: O | O4: POSTE B | P4: 24 | Q4: =VLOOKUP(P4,Tabela13[],2,0) -> 0 | R4: =VLOOKUP(P4,Tabela13[],3,0) -> 0
B5: 3 | F5: =IF(Tabela13[[#This Row],[X / LAT / E]]="","",VLOOKUP(Tabela13[[#This Row],[PONTO]],RAMAIS_ATUAL,IF(PROJ1!$J$2="SIM",25,23),0)) | G5: =SQRT((D6-Tabela13[[#This Row],[Y / LON / N]])^2+(C6-Tabela13[[#This Row],[X / LAT / E]])^2) -> 0 | I5: 3 | M5: O
B6: 4 | F6: =IF(Tabela13[[#This Row],[X / LAT / E]]="","",VLOOKUP(Tabela13[[#This Row],[PONTO]],RAMAIS_ATUAL,IF(PROJ1!$J$2="SIM",25,23),0)) | G6: =SQRT((D7-Tabela13[[#This Row],[Y / LON / N]])^2+(C7-Tabela13[[#This Row],[X / LAT / E]])^2) -> 0 | I6: 4
B7: 5 | F7: =IF(Tabela13[[#This Row],[X / LAT / E]]="","",VLOOKUP(Tabela13[[#This Row],[PONTO]],RAMAIS_ATUAL,IF(PROJ1!$J$2="SIM",25,23),0)) | G7: =SQRT((D8-Tabela13[[#This Row],[Y / LON / N]])^2+(C8-Tabela13[[#This Row],[X / LAT / E]])^2) -> 0 | I7: 5 | Q7: DISTANCIA | R7: =ROUNDDOWN(SQRT((R4-R3)^2+(Q4-Q3)^2),0) -> 0
B8: 6 | F8: =IF(Tabela13[[#This Row],[X / LAT / E]]="","",VLOOKUP(Tabela13[[#This Row],[PONTO]],RAMAIS_ATUAL,IF(PROJ1!$J$2="SIM",25,23),0)) | G8: =SQRT((D9-Tabela13[[#This Row],[Y / LON / N]])^2+(C9-Tabela13[[#This Row],[X / LAT / E]])^2) -> 0 | I8: 6
B9: 7 | F9: =IF(Tabela13[[#This Row],[X / LAT / E]]="","",VLOOKUP(Tabela13[[#This Row],[PONTO]],RAMAIS_ATUAL,IF(PROJ1!$J$2="SIM",25,23),0)) | G9: =SQRT((D10-Tabela13[[#This Row],[Y / LON / N]])^2+(C10-Tabela13[[#This Row],[X / LAT / E]])^2) -> 0 | I9: 7
B10: 8 | F10: =IF(Tabela13[[#This Row],[X / LAT / E]]="","",VLOOKUP(Tabela13[[#This Row],[PONTO]],RAMAIS_ATUAL,IF(PROJ1!$J$2="SIM",25,23),0)) | G10: =SQRT((D11-Tabela13[[#This Row],[Y / LON / N]])^2+(C11-Tabela13[[#This Row],[X / LAT / E]])^2) -> 0 | I10: 8 | O10: CENTRO DE CARGA
B11: 9 | F11: =IF(Tabela13[[#This Row],[X / LAT / E]]="","",VLOOKUP(Tabela13[[#This Row],[PONTO]],RAMAIS_ATUAL,IF(PROJ1!$J$2="SIM",25,23),0)) | G11: =SQRT((D12-Tabela13[[#This Row],[Y / LON / N]])^2+(C12-Tabela13[[#This Row],[X / LAT / E]])^2) -> 0 | I11: 9
B12: 10 | F12: =IF(Tabela13[[#This Row],[X / LAT / E]]="","",VLOOKUP(Tabela13[[#This Row],[PONTO]],RAMAIS_ATUAL,IF(PROJ1!$J$2="SIM",25,23),0)) | G12: =SQRT((D13-Tabela13[[#This Row],[Y / LON / N]])^2+(C13-Tabela13[[#This Row],[X / LAT / E]])^2) -> 0 | I12: 10 | O12: X | P12: =IFERROR(SUMPRODUCT($F$3:$F$63,Tabela13[X / LAT / E])/SUM(F3:F63),"INSERIR DADOS") -> INSERIR DADOS
B13: 11 | F13: =IF(Tabela13[[#This Row],[X / LAT / E]]="","",VLOOKUP(Tabela13[[#This Row],[PONTO]],RAMAIS_ATUAL,IF(PROJ1!$J$2="SIM",25,23),0)) | G13: =SQRT((D14-Tabela13[[#This Row],[Y / LON / N]])^2+(C14-Tabela13[[#This Row],[X / LAT / E]])^2) -> 0 | I13: 11 | O13: Y | P13: =IFERROR(SUMPRODUCT(F3:F63,Tabela13[Y / LON / N])/SUM($F$3:$F$63),"INSERIR DADOS") -> INSERIR DADOS
B14: 12 | F14: =IF(Tabela13[[#This Row],[X / LAT / E]]="","",VLOOKUP(Tabela13[[#This Row],[PONTO]],RAMAIS_ATUAL,IF(PROJ1!$J$2="SIM",25,23),0)) | G14: =SQRT((D15-Tabela13[[#This Row],[Y / LON / N]])^2+(C15-Tabela13[[#This Row],[X / LAT / E]])^2) -> 0 | I14: 12
B15: 13 | F15: =IF(Tabela13[[#This Row],[X / LAT / E]]="","",VLOOKUP(Tabela13[[#This Row],[PONTO]],RAMAIS_ATUAL,IF(PROJ1!$J$2="SIM",25,23),0)) | G15: =SQRT((D16-Tabela13[[#This Row],[Y / LON / N]])^2+(C16-Tabela13[[#This Row],[X / LAT / E]])^2) -> 0 | I15: 13
B16: 14 | F16: =IF(Tabela13[[#This Row],[X / LAT / E]]="","",VLOOKUP(Tabela13[[#This Row],[PONTO]],RAMAIS_ATUAL,IF(PROJ1!$J$2="SIM",25,23),0)) | G16: =SQRT((D17-Tabela13[[#This Row],[Y / LON / N]])^2+(C17-Tabela13[[#This Row],[X / LAT / E]])^2) -> 0 | I16: 14
B17: 15 | F17: =IF(Tabela13[[#This Row],[X / LAT / E]]="","",VLOOKUP(Tabela13[[#This Row],[PONTO]],RAMAIS_ATUAL,IF(PROJ1!$J$2="SIM",25,23),0)) | G17: =SQRT((D18-Tabela13[[#This Row],[Y / LON / N]])^2+(C18-Tabela13[[#This Row],[X / LAT / E]])^2) -> 0 | I17: 15
B18: 16 | F18: =IF(Tabela13[[#This Row],[X / LAT / E]]="","",VLOOKUP(Tabela13[[#This Row],[PONTO]],RAMAIS_ATUAL,IF(PROJ1!$J$2="SIM",25,23),0)) | G18: =SQRT((D19-Tabela13[[#This Row],[Y / LON / N]])^2+(C19-Tabela13[[#This Row],[X / LAT / E]])^2) -> 0 | I18: 15
B19: 17 | F19: =IF(Tabela13[[#This Row],[X / LAT / E]]="","",VLOOKUP(Tabela13[[#This Row],[PONTO]],RAMAIS_ATUAL,IF(PROJ1!$J$2="SIM",25,23),0)) | G19: =SQRT((D20-Tabela13[[#This Row],[Y / LON / N]])^2+(C20-Tabela13[[#This Row],[X / LAT / E]])^2) -> 0 | I19: 16
B20: 18 | F20: =IF(Tabela13[[#This Row],[X / LAT / E]]="","",VLOOKUP(Tabela13[[#This Row],[PONTO]],RAMAIS_ATUAL,IF(PROJ1!$J$2="SIM",25,23),0)) | G20: =SQRT((D21-Tabela13[[#This Row],[Y / LON / N]])^2+(C21-Tabela13[[#This Row],[X / LAT / E]])^2) -> 0 | I20: 17
B21: 19 | F21: =IF(Tabela13[[#This Row],[X / LAT / E]]="","",VLOOKUP(Tabela13[[#This Row],[PONTO]],RAMAIS_ATUAL,IF(PROJ1!$J$2="SIM",25,23),0)) | G21: =SQRT((D22-Tabela13[[#This Row],[Y / LON / N]])^2+(C22-Tabela13[[#This Row],[X / LAT / E]])^2) -> 0 | I21: 18
B22: 20 | F22: =IF(Tabela13[[#This Row],[X / LAT / E]]="","",VLOOKUP(Tabela13[[#This Row],[PONTO]],RAMAIS_ATUAL,IF(PROJ1!$J$2="SIM",25,23),0)) | G22: =SQRT((D23-Tabela13[[#This Row],[Y / LON / N]])^2+(C23-Tabela13[[#This Row],[X / LAT / E]])^2) -> 0 | I22: 19
B23: 21 | F23: =IF(Tabela13[[#This Row],[X / LAT / E]]="","",VLOOKUP(Tabela13[[#This Row],[PONTO]],RAMAIS_ATUAL,IF(PROJ1!$J$2="SIM",25,23),0)) | G23: =SQRT((D24-Tabela13[[#This Row],[Y / LON / N]])^2+(C24-Tabela13[[#This Row],[X / LAT / E]])^2) -> 0 | I23: 20
B24: 22 | F24: =IF(Tabela13[[#This Row],[X / LAT / E]]="","",VLOOKUP(Tabela13[[#This Row],[PONTO]],RAMAIS_ATUAL,IF(PROJ1!$J$2="SIM",25,23),0)) | G24: =SQRT((D25-Tabela13[[#This Row],[Y / LON / N]])^2+(C25-Tabela13[[#This Row],[X / LAT / E]])^2) -> 0 | I24: 21
B25: 23 | F25: =IF(Tabela13[[#This Row],[X / LAT / E]]="","",VLOOKUP(Tabela13[[#This Row],[PONTO]],RAMAIS_ATUAL,IF(PROJ1!$J$2="SIM",25,23),0)) | G25: =SQRT((D26-Tabela13[[#This Row],[Y / LON / N]])^2+(C26-Tabela13[[#This Row],[X / LAT / E]])^2) -> 0 | I25: 26
... B32: 30 | F32: =IF(Tabela13[[#This Row],[X / LAT / E]]="","",VLOOKUP(Tabela13[[#This Row],[PONTO]],RAMAIS_ATUAL,IF(PROJ1!$J$2="SIM",25,23),0)) | G32: =SQRT((D33-Tabela13[[#This Row],[Y / LON / N]])^2+(C33-Tabela13[[#This Row],[X / LAT / E]])^2) -> 0 | I32: 29
B33: 31 | F33: =IF(Tabela13[[#This Row],[X / LAT / E]]="","",VLOOKUP(Tabela13[[#This Row],[PONTO]],RAMAIS_ATUAL,IF(PROJ1!$J$2="SIM",25,23),0)) | G33: =SQRT((D34-Tabela13[[#This Row],[Y / LON / N]])^2+(C34-Tabela13[[#This Row],[X / LAT / E]])^2) -> 0
B34: 32 | F34: =IF(Tabela13[[#This Row],[X / LAT / E]]="","",VLOOKUP(Tabela13[[#This Row],[PONTO]],RAMAIS_ATUAL,IF(PROJ1!$J$2="SIM",25,23),0)) | G34: =SQRT((D35-Tabela13[[#This Row],[Y / LON / N]])^2+(C35-Tabela13[[#This Row],[X / LAT / E]])^2) -> 0
B35: 33 | F35: =IF(Tabela13[[#This Row],[X / LAT / E]]="","",VLOOKUP(Tabela13[[#This Row],[PONTO]],RAMAIS_ATUAL,IF(PROJ1!$J$2="SIM",25,23),0)) | G35: =SQRT((D36-Tabela13[[#This Row],[Y / LON / N]])^2+(C36-Tabela13[[#This Row],[X / LAT / E]])^2) -> 0
B36: 34 | F36: =IF(Tabela13[[#This Row],[X / LAT / E]]="","",VLOOKUP(Tabela13[[#This Row],[PONTO]],RAMAIS_ATUAL,IF(PROJ1!$J$2="SIM",25,23),0)) | G36: =SQRT((D37-Tabela13[[#This Row],[Y / LON / N]])^2+(C37-Tabela13[[#This Row],[X / LAT / E]])^2) -> 0
B37: 35 | F37: =IF(Tabela13[[#This Row],[X / LAT / E]]="","",VLOOKUP(Tabela13[[#This Row],[PONTO]],RAMAIS_ATUAL,IF(PROJ1!$J$2="SIM",25,23),0)) | G37: =SQRT((D38-Tabela13[[#This Row],[Y / LON / N]])^2+(C38-Tabela13[[#This Row],[X / LAT / E]])^2) -> 0
B38: 36 | F38: =IF(Tabela13[[#This Row],[X / LAT / E]]="","",VLOOKUP(Tabela13[[#This Row],[PONTO]],RAMAIS_ATUAL,IF(PROJ1!$J$2="SIM",25,23),0)) | G38: =SQRT((D39-Tabela13[[#This Row],[Y / LON / N]])^2+(C39-Tabela13[[#This Row],[X / LAT / E]])^2) -> 0
B39: 37 | F39: =IF(Tabela13[[#This Row],[X / LAT / E]]="","",VLOOKUP(Tabela13[[#This Row],[PONTO]],RAMAIS_ATUAL,IF(PROJ1!$J$2="SIM",25,23),0)) | G39: =SQRT((D40-Tabela13[[#This Row],[Y / LON / N]])^2+(C40-Tabela13[[#This Row],[X / LAT / E]])^2) -> 0
B40: 38 | F40: =IF(Tabela13[[#This Row],[X / LAT / E]]="","",VLOOKUP(Tabela13[[#This Row],[PONTO]],RAMAIS_ATUAL,IF(PROJ1!$J$2="SIM",25,23),0)) | G40: =SQRT((D41-Tabela13[[#This Row],[Y / LON / N]])^2+(C41-Tabela13[[#This Row],[X / LAT / E]])^2) -> 0
B41: 38 | F41: =IF(Tabela13[[#This Row],[X / LAT / E]]="","",VLOOKUP(Tabela13[[#This Row],[PONTO]],RAMAIS_ATUAL,IF(PROJ1!$J$2="SIM",25,23),0)) | G41: =SQRT((D42-Tabela13[[#This Row],[Y / LON / N]])^2+(C42-Tabela13[[#This Row],[X / LAT / E]])^2) -> 0
B42: 39 | F42: =IF(Tabela13[[#This Row],[X / LAT / E]]="","",VLOOKUP(Tabela13[[#This Row],[PONTO]],RAMAIS_ATUAL,IF(PROJ1!$J$2="SIM",25,23),0)) | G42: =SQRT((D43-Tabela13[[#This Row],[Y / LON / N]])^2+(C43-Tabela13[[#This Row],[X / LAT / E]])^2) -> 0
B43: 40 | F43: =IF(Tabela13[[#This Row],[X / LAT / E]]="","",VLOOKUP(Tabela13[[#This Row],[PONTO]],RAMAIS_ATUAL,IF(PROJ1!$J$2="SIM",25,23),0)) | G43: =SQRT((D44-Tabela13[[#This Row],[Y / LON / N]])^2+(C44-Tabela13[[#This Row],[X / LAT / E]])^2) -> 0
B44: 41 | F44: =IF(Tabela13[[#This Row],[X / LAT / E]]="","",VLOOKUP(Tabela13[[#This Row],[PONTO]],RAMAIS_ATUAL,IF(PROJ1!$J$2="SIM",25,23),0)) | G44: =SQRT((D45-Tabela13[[#This Row],[Y / LON / N]])^2+(C45-Tabela13[[#This Row],[X / LAT / E]])^2) -> 0
... B63: 60 | F63: =IF(Tabela13[[#This Row],[X / LAT / E]]="","",VLOOKUP(Tabela13[[#This Row],[PONTO]],RAMAIS_ATUAL,IF(PROJ1!$J$2="SIM",25,23),0)) | G63: =SQRT((D64-Tabela13[[#This Row],[Y / LON / N]])^2+(C64-Tabela13[[#This Row],[X / LAT / E]])^2) -> 0
B64: 61
B65: 62
...

Sheet SUGESTAO_CORTES
A1: PAINEL DE SUGESTAO DE CORTES (HEURISTICO) | K1: PARAMETROS SCORE
K2: Peso carga acumulada | L2: 0.3 | M2: 1 | N2: =IFERROR(IF(INDEX(GERAL[PONTO],M2)="","",INDEX(GERAL[PONTO],M2)),"") -> 1 | O2: =IF(N2="","",IFERROR(INDEX(GERAL[ACUMULADA],1),0)) -> 127.70729 | P2: =IF(O2="","",$B$11-O2) -> -87.061694 | Q2: =IF(O2="","",IF(O2*1.15<=30,30,IF(O2*1.15<=45,45,IF(O2*1.15<=75,75,IF(O2*1.15<=112.5,112.5,IF(O2*1.15<=150,150,IF(O2*1.15<=225,225,300))))))) -> 150 | R2: =IF(Q2="","",IFERROR(O2/Q2,0)) -> 0.85138196 | S2: =IF(N2="","",IFERROR(INDEX(Tabela7[QT %],MATCH(N2,Tabela7[PONTO],0)),0)) -> 0.049510527 | T2: =IF(O2="","",IFERROR(1-ABS(O2-P2)/$B$11,0)) -> -4.2839419 | U2: =IF(N2="","",IF($B$9>$B$8,IFERROR((INDEX(GERAL[SNAP],1)-$B$8)/($B$9-$B$8),0),0)) -> 0 | V2: =IF(OR(N2="",W2<>"LADO 1"),"",$L$2*IFERROR(O2/$B$11,0)+$L$3*IF($D$11>0,IFERROR(S2/$D$11,0),0)+$L$4*IFERROR(T2,0)-$L$5*IFERROR(U2,0)-$L$6*MAX(0,IFERROR(R2,0)-$L$7)+ROW()/1000000) | W2: =IFERROR(INDEX(GERAL[LADO],1),"") -> TRAFO | Y2: =IFERROR(IF(INDEX(GERAL[PONTO],M2)="","",INDEX(GERAL[PONTO],M2)),"") -> 1 | Z2: =IF(Y2="","",IFERROR(INDEX(GERAL[ACUMULADA],1),0)) -> 127.70729 | AA2: =IF(Z2="","",$B$31-Z2) -> -21.675294 | AB2: =IF(Z2="","",IF(Z2*1.15<=30,30,IF(Z2*1.15<=45,45,IF(Z2*1.15<=75,75,IF(Z2*1.15<=112.5,112.5,IF(Z2*1.15<=150,150,IF(Z2*1.15<=225,225,300))))))) -> 150 | AC2: =IF(AB2="","",IFERROR(Z2/AB2,0)) -> 0.85138196 | AD2: =IF(Y2="","",IFERROR(INDEX(DIR_ATUAL[QT %],MATCH(Y2,DIR_ATUAL[PONTO],0)),0)) -> 0.049510527 | AE2: =IF(Z2="","",IFERROR(1-ABS(Z2-AA2)/$B$31,0)) -> -0.40884439 | AF2: =IF(Y2="","",IF($E$9>$E$8,IFERROR((INDEX(GERAL[SNAP],1)-$E$8)/($E$9-$E$8),0),0)) -> 0 | AG2: =IF(OR(Y2="",AH2<>"LADO 2"),"",$L$2*IFERROR(Z2/$B$31,0)+$L$3*IF($D$31>0,IFERROR(AD2/$D$31,0),0)+$L$4*IFERROR(AE2,0)-$L$5*IFERROR(AF2,0)-$L$6*MAX(0,IFERROR(AC2,0)-$L$7)+ROW()/1000000) | AH2: =IFERROR(INDEX(GERAL[LADO],1),"") -> TRAFO
A3: Arquivo analisado | D3: Cenario 2 trafos | K3: Peso QT | L3: 0.69 | M3: 2 | N3: =IFERROR(IF(INDEX(GERAL[PONTO],M3)="","",INDEX(GERAL[PONTO],M3)),"") | O3: =IF(N3="","",IFERROR(INDEX(GERAL[ACUMULADA],2),0)) | P3: =IF(O3="","",$B$11-O3) | Q3: =IF(O3="","",IF(O3*1.15<=30,30,IF(O3*1.15<=45,45,IF(O3*1.15<=75,75,IF(O3*1.15<=112.5,112.5,IF(O3*1.15<=150,150,IF(O3*1.15<=225,225,300))))))) | R3: =IF(Q3="","",IFERROR(O3/Q3,0)) | S3: =IF(N3="","",IFERROR(INDEX(Tabela7[QT %],MATCH(N3,Tabela7[PONTO],0)),0)) | T3: =IF(O3="","",IFERROR(1-ABS(O3-P3)/$B$11,0)) | U3: =IF(N3="","",IF($B$9>$B$8,IFERROR((INDEX(GERAL[SNAP],2)-$B$8)/($B$9-$B$8),0),0)) | V3: =IF(OR(N3="",W3<>"LADO 1"),"",$L$2*IFERROR(O3/$B$11,0)+$L$3*IF($D$11>0,IFERROR(S3/$D$11,0),0)+$L$4*IFERROR(T3,0)-$L$5*IFERROR(U3,0)-$L$6*MAX(0,IFERROR(R3,0)-$L$7)+ROW()/1000000) | W3: =IFERROR(INDEX(GERAL[LADO],2),"") -> 0 | Y3: =IFERROR(IF(INDEX(GERAL[PONTO],M3)="","",INDEX(GERAL[PONTO],M3)),"") | Z3: =IF(Y3="","",IFERROR(INDEX(GERAL[ACUMULADA],2),0)) | AA3: =IF(Z3="","",$B$31-Z3) | AB3: =IF(Z3="","",IF(Z3*1.15<=30,30,IF(Z3*1.15<=45,45,IF(Z3*1.15<=75,75,IF(Z3*1.15<=112.5,112.5,IF(Z3*1.15<=150,150,IF(Z3*1.15<=225,225,300))))))) | AC3: =IF(AB3="","",IFERROR(Z3/AB3,0)) | AD3: =IF(Y3="","",IFERROR(INDEX(DIR_ATUAL[QT %],MATCH(Y3,DIR_ATUAL[PONTO],0)),0)) | AE3: =IF(Z3="","",IFERROR(1-ABS(Z3-AA3)/$B$31,0)) | AF3: =IF(Y3="","",IF($E$9>$E$8,IFERROR((INDEX(GERAL[SNAP],2)-$E$8)/($E$9-$E$8),0),0)) | AG3: =IF(OR(Y3="",AH3<>"LADO 2"),"",$L$2*IFERROR(Z3/$B$31,0)+$L$3*IF($D$31>0,IFERROR(AD3/$D$31,0),0)+$L$4*IFERROR(AE3,0)-$L$5*IFERROR(AF3,0)-$L$6*MAX(0,IFERROR(AC3,0)-$L$7)+ROW()/1000000) | AH3: =IFERROR(INDEX(GERAL[LADO],2),"") -> 0
A4: Gerado em | D4: LADO 1 | E4: =SUMIFS(GERAL[TOTAL DO TRECHO],GERAL[LADO],"LADO 1") -> 40.6456 | F4: =IF(E4*1.15<=30,30,IF(E4*1.15<=45,45,IF(E4*1.15<=75,75,IF(E4*1.15<=112.5,112.5,IF(E4*1.15<=150,150,IF(E4*1.15<=225,225,300)))))) -> 75 | G4: =IFERROR(E4/F4,0) -> 0.54194133 | K4: Peso balanceamento | L4: 0.01 | M4: 3 | N4: =IFERROR(IF(INDEX(GERAL[PONTO],M4)="","",INDEX(GERAL[PONTO],M4)),"") -> 2 | O4: =IF(N4="","",IFERROR(INDEX(GERAL[ACUMULADA],3),0)) -> 36.2276 | P4: =IF(O4="","",$B$11-O4) -> 4.418 | Q4: =IF(O4="","",IF(O4*1.15<=30,30,IF(O4*1.15<=45,45,IF(O4*1.15<=75,75,IF(O4*1.15<=112.5,112.5,IF(O4*1.15<=150,150,IF(O4*1.15<=225,225,300))))))) -> 45 | R4: =IF(Q4="","",IFERROR(O4/Q4,0)) -> 0.80505778 | S4: =IF(N4="","",IFERROR(INDEX(Tabela7[QT %],MATCH(N4,Tabela7[PONTO],0)),0)) -> 0.067310028 | T4: =IF(O4="","",IFERROR(1-ABS(O4-P4)/$B$11,0)) -> 0.2173913 | U4: =IF(N4="","",IF($B$9>$B$8,IFERROR((INDEX(GERAL[SNAP],3)-$B$8)/($B$9-$B$8),0),0)) -> 0 | V4: =IF(OR(N4="",W4<>"LADO 1"),"",$L$2*IFERROR(O4/$B$11,0)+$L$3*IF($D$11>0,IFERROR(S4/$D$11,0),0)+$L$4*IFERROR(T4,0)-$L$5*IFERROR(U4,0)-$L$6*MAX(0,IFERROR(R4,0)-$L$7)+ROW()/1000000) -> 0.82673365 | W4: =IFERROR(INDEX(GERAL[LADO],3),"") -> LADO 1 | Y4: =IFERROR(IF(INDEX(GERAL[PONTO],M4)="","",INDEX(GERAL[PONTO],M4)),"") -> 2 | Z4: =IF(Y4="","",IFERROR(INDEX(GERAL[ACUMULADA],3),0)) -> 36.2276 | AA4: =IF(Z4="","",$B$31-Z4) -> 69.8044 | AB4: =IF(Z4="","",IF(Z4*1.15<=30,30,IF(Z4*1.15<=45,45,IF(Z4*1.15<=75,75,IF(Z4*1.15<=112.5,112.5,IF(Z4*1.15<=150,150,IF(Z4*1.15<=225,225,300))))))) -> 45 | AC4: =IF(AB4="","",IFERROR(Z4/AB4,0)) -> 0.80505778 | AD4: =IF(Y4="","",IFERROR(INDEX(DIR_ATUAL[QT %],MATCH(Y4,DIR_ATUAL[PONTO],0)),0)) -> 0 | AE4: =IF(Z4="","",IFERROR(1-ABS(Z4-AA4)/$B$31,0)) -> 0.68333333 | AF4: =IF(Y4="","",IF($E$9>$E$8,IFERROR((INDEX(GERAL[SNAP],3)-$E$8)/($E$9-$E$8),0),0)) -> 0 | AG4: =IF(OR(Y4="",AH4<>"LADO 2"),"",$L$2*IFERROR(Z4/$B$31,0)+$L$3*IF($D$31>0,IFERROR(AD4/$D$31,0),0)+$L$4*IFERROR(AE4,0)-$L$5*IFERROR(AF4,0)-$L$6*MAX(0,IFERROR(AC4,0)-$L$7)+ROW()/1000000) | AH4: =IFERROR(INDEX(GERAL[LADO],3),"") -> LADO 1
A5: Demanda atual (kVA) | B5: =DB!K7/0.85 -> 150.24388 | D5: LADO 2 | E5: =SUMIFS(GERAL[TOTAL DO TRECHO],GERAL[LADO],"LADO 2") -> 106.032 | F5: =IF(E5*1.15<=30,30,IF(E5*1.15<=45,45,IF(E5*1.15<=75,75,IF(E5*1.15<=112.5,112.5,IF(E5*1.15<=150,150,IF(E5*1.15<=225,225,300)))))) -> 150 | G5: =IFERROR(E5/F5,0) -> 0.70688 | K5: Penalidade distancia | L5: 0.05 | M5: 4 | N5: =IFERROR(IF(INDEX(GERAL[PONTO],M5)="","",INDEX(GERAL[PONTO],M5)),"") -> 3 | O5: =IF(N5="","",IFERROR(INDEX(GERAL[ACUMULADA],4),0)) -> 36.2276 | P5: =IF(O5="","",$B$11-O5) -> 4.418 | Q5: =IF(O5="","",IF(O5*1.15<=30,30,IF(O5*1.15<=45,45,IF(O5*1.15<=75,75,IF(O5*1.15<=112.5,112.5,IF(O5*1.15<=150,150,IF(O5*1.15<=225,225,300))))))) -> 45 | R5: =IF(Q5="","",IFERROR(O5/Q5,0)) -> 0.80505778 | S5: =IF(N5="","",IFERROR(INDEX(Tabela7[QT %],MATCH(N5,Tabela7[PONTO],0)),0)) -> 0.07574137 | T5: =IF(O5="","",IFERROR(1-ABS(O5-P5)/$B$11,0)) -> 0.2173913 | U5: =IF(N5="","",IF($B$9>$B$8,IFERROR((INDEX(GERAL[SNAP],4)-$B$8)/($B$9-$B$8),0),0)) -> 0 | V5: =IF(OR(N5="",W5<>"LADO 1"),"",$L$2*IFERROR(O5/$B$11,0)+$L$3*IF($D$11>0,IFERROR(S5/$D$11,0),0)+$L$4*IFERROR(T5,0)-$L$5*IFERROR(U5,0)-$L$6*MAX(0,IFERROR(R5,0)-$L$7)+ROW()/1000000) -> 0.8965258 | W5: =IFERROR(INDEX(GERAL[LADO],4),"") -> LADO 1 | Y5: =IFERROR(IF(INDEX(GERAL[PONTO],M5)="","",INDEX(GERAL[PONTO],M5)),"") -> 3 | Z5: =IF(Y5="","",IFERROR(INDEX(GERAL[ACUMULADA],4),0)) -> 36.2276 | AA5: =IF(Z5="","",$B$31-Z5) -> 69.8044 | AB5: =IF(Z5="","",IF(Z5*1.15<=30,30,IF(Z5*1.15<=45,45,IF(Z5*1.15<=75,75,IF(Z5*1.15<=112.5,112.5,IF(Z5*1.15<=150,150,IF(Z5*1.15<=225,225,300))))))) -> 45 | AC5: =IF(AB5="","",IFERROR(Z5/AB5,0)) -> 0.80505778 | AD5: =IF(Y5="","",IFERROR(INDEX(DIR_ATUAL[QT %],MATCH(Y5,DIR_ATUAL[PONTO],0)),0)) -> 0 | AE5: =IF(Z5="","",IFERROR(1-ABS(Z5-AA5)/$B$31,0)) -> 0.68333333 | AF5: =IF(Y5="","",IF($E$9>$E$8,IFERROR((INDEX(GERAL[SNAP],4)-$E$8)/($E$9-$E$8),0),0)) -> 0 | AG5: =IF(OR(Y5="",AH5<>"LADO 2"),"",$L$2*IFERROR(Z5/$B$31,0)+$L$3*IF($D$31>0,IFERROR(AD5/$D$31,0),0)+$L$4*IFERROR(AE5,0)-$L$5*IFERROR(AF5,0)-$L$6*MAX(0,IFERROR(AC5,0)-$L$7)+ROW()/1000000) | AH5: =IFERROR(INDEX(GERAL[LADO],4),"") -> LADO 1
A6: Trafo atual (kVA) | B6: =DB!K6 -> 150 | D6: Status | E6: =IF(AND(G4<=0.85,G5<=0.85),"OK","SPLIT_MAIOR_LADO") -> OK | K6: Penalidade saturacao | L6: 0.2 | M6: 5 | N6: =IFERROR(IF(INDEX(GERAL[PONTO],M6)="","",INDEX(GERAL[PONTO],M6)),"") -> 4 | O6: =IF(N6="","",IFERROR(INDEX(GERAL[ACUMULADA],5),0)) -> 22.5224 | P6: =IF(O6="","",$B$11-O6) -> 18.1232 | Q6: =IF(O6="","",IF(O6*1.15<=30,30,IF(O6*1.15<=45,45,IF(O6*1.15<=75,75,IF(O6*1.15<=112.5,112.5,IF(O6*1.15<=150,150,IF(O6*1.15<=225,225,300))))))) -> 30 | R6: =IF(Q6="","",IFERROR(O6/Q6,0)) -> 0.75074667 | S6: =IF(N6="","",IFERROR(INDEX(Tabela7[QT %],MATCH(N6,Tabela7[PONTO],0)),0)) -> 0.080756952 | T6: =IF(O6="","",IFERROR(1-ABS(O6-P6)/$B$11,0)) -> 0.89176688 | U6: =IF(N6="","",IF($B$9>$B$8,IFERROR((INDEX(GERAL[SNAP],5)-$B$8)/($B$9-$B$8),0),0)) -> 0 | V6: =IF(OR(N6="",W6<>"LADO 1"),"",$L$2*IFERROR(O6/$B$11,0)+$L$3*IF($D$11>0,IFERROR(S6/$D$11,0),0)+$L$4*IFERROR(T6,0)-$L$5*IFERROR(U6,0)-$L$6*MAX(0,IFERROR(R6,0)-$L$7)+ROW()/1000000) -> 0.84363112 | W6: =IFERROR(INDEX(GERAL[LADO],5),"") -> LADO 1 | Y6: =IFERROR(IF(INDEX(GERAL[PONTO],M6)="","",INDEX(GERAL[PONTO],M6)),"") -> 4 | Z6: =IF(Y6="","",IFERROR(INDEX(GERAL[ACUMULADA],5),0)) -> 22.5224 | AA6: =IF(Z6="","",$B$31-Z6) -> 83.5096 | AB6: =IF(Z6="","",IF(Z6*1.15<=30,30,IF(Z6*1.15<=45,45,IF(Z6*1.15<=75,75,IF(Z6*1.15<=112.5,112.5,IF(Z6*1.15<=150,150,IF(Z6*1.15<=225,225,300))))))) -> 30 | AC6: =IF(AB6="","",IFERROR(Z6/AB6,0)) -> 0.75074667 | AD6: =IF(Y6="","",IFERROR(INDEX(DIR_ATUAL[QT %],MATCH(Y6,DIR_ATUAL[PONTO],0)),0)) -> 0 | AE6: =IF(Z6="","",IFERROR(1-ABS(Z6-AA6)/$B$31,0)) -> 0.4248227 | AF6: =IF(Y6="","",IF($E$9>$E$8,IFERROR((INDEX(GERAL[SNAP],5)-$E$8)/($E$9-$E$8),0),0)) -> 0 | AG6: =IF(OR(Y6="",AH6<>"LADO 2"),"",$L$2*IFERROR(Z6/$B$31,0)+$L$3*IF($D$31>0,IFERROR(AD6/$D$31,0),0)+$L$4*IFERROR(AE6,0)-$L$5*IFERROR(AF6,0)-$L$6*MAX(0,IFERROR(AC6,0)-$L$7)+ROW()/1000000) | AH6: =IFERROR(INDEX(GERAL[LADO],5),"") -> LADO 1
A7: Saturacao atual | B7: =IFERROR(B5/B6,0) -> 1.0016258 | K7: Limite sat pos-corte | L7: 0.85 | M7: 6 | N7: =IFERROR(IF(INDEX(GERAL[PONTO],M7)="","",INDEX(GERAL[PONTO],M7)),"") | O7: =IF(N7="","",IFERROR(INDEX(GERAL[ACUMULADA],6),0)) | P7: =IF(O7="","",$B$11-O7) | Q7: =IF(O7="","",IF(O7*1.15<=30,30,IF(O7*1.15<=45,45,IF(O7*1.15<=75,75,IF(O7*1.15<=112.5,112.5,IF(O7*1.15<=150,150,IF(O7*1.15<=225,225,300))))))) | R7: =IF(Q7="","",IFERROR(O7/Q7,0)) | S7: =IF(N7="","",IFERROR(INDEX(Tabela7[QT %],MATCH(N7,Tabela7[PONTO],0)),0)) | T7: =IF(O7="","",IFERROR(1-ABS(O7-P7)/$B$11,0)) | U7: =IF(N7="","",IF($B$9>$B$8,IFERROR((INDEX(GERAL[SNAP],6)-$B$8)/($B$9-$B$8),0),0)) | V7: =IF(OR(N7="",W7<>"LADO 1"),"",$L$2*IFERROR(O7/$B$11,0)+$L$3*IF($D$11>0,IFERROR(S7/$D$11,0),0)+$L$4*IFERROR(T7,0)-$L$5*IFERROR(U7,0)-$L$6*MAX(0,IFERROR(R7,0)-$L$7)+ROW()/1000000) | W7: =IFERROR(INDEX(GERAL[LADO],6),"") -> 0 | Y7: =IFERROR(IF(INDEX(GERAL[PONTO],M7)="","",INDEX(GERAL[PONTO],M7)),"") | Z7: =IF(Y7="","",IFERROR(INDEX(GERAL[ACUMULADA],6),0)) | AA7: =IF(Z7="","",$B$31-Z7) | AB7: =IF(Z7="","",IF(Z7*1.15<=30,30,IF(Z7*1.15<=45,45,IF(Z7*1.15<=75,75,IF(Z7*1.15<=112.5,112.5,IF(Z7*1.15<=150,150,IF(Z7*1.15<=225,225,300))))))) | AC7: =IF(AB7="","",IFERROR(Z7/AB7,0)) | AD7: =IF(Y7="","",IFERROR(INDEX(DIR_ATUAL[QT %],MATCH(Y7,DIR_ATUAL[PONTO],0)),0)) | AE7: =IF(Z7="","",IFERROR(1-ABS(Z7-AA7)/$B$31,0)) | AF7: =IF(Y7="","",IF($E$9>$E$8,IFERROR((INDEX(GERAL[SNAP],6)-$E$8)/($E$9-$E$8),0),0)) | AG7: =IF(OR(Y7="",AH7<>"LADO 2"),"",$L$2*IFERROR(Z7/$B$31,0)+$L$3*IF($D$31>0,IFERROR(AD7/$D$31,0),0)+$L$4*IFERROR(AE7,0)-$L$5*IFERROR(AF7,0)-$L$6*MAX(0,IFERROR(AC7,0)-$L$7)+ROW()/1000000) | AH7: =IFERROR(INDEX(GERAL[LADO],6),"") -> 0
B8: =IFERROR(MINIFS(GERAL[SNAP],GERAL[LADO],"ESQUERDO"),0) -> 0 | E8: =IFERROR(MINIFS(GERAL[SNAP],GERAL[LADO],"DIREITO"),0) -> 0 | K8: Soma pesos (ideal 1,00) | L8: =L2+L3+L4 -> 1 | M8: 7 | N8: =IFERROR(IF(INDEX(GERAL[PONTO],M8)="","",INDEX(GERAL[PONTO],M8)),"") -> 5 | O8: =IF(N8="","",IFERROR(INDEX(GERAL[ACUMULADA],7),0)) -> 80.1256 | P8: =IF(O8="","",$B$11-O8) -> -39.48 | Q8: =IF(O8="","",IF(O8*1.15<=30,30,IF(O8*1.15<=45,45,IF(O8*1.15<=75,75,IF(O8*1.15<=112.5,112.5,IF(O8*1.15<=150,150,IF(O8*1.15<=225,225,300))))))) -> 112.5 | R8: =IF(Q8="","",IFERROR(O8/Q8,0)) -> 0.71222756 | S8: =IF(N8="","",IFERROR(INDEX(Tabela7[QT %],MATCH(N8,Tabela7[PONTO],0)),0)) -> 0 | T8: =IF(O8="","",IFERROR(1-ABS(O8-P8)/$B$11,0)) -> -1.9426457 | U8: =IF(N8="","",IF($B$9>$B$8,IFERROR((INDEX(GERAL[SNAP],7)-$B$8)/($B$9-$B$8),0),0)) -> 0 | V8: =IF(OR(N8="",W8<>"LADO 1"),"",$L$2*IFERROR(O8/$B$11,0)+$L$3*IF($D$11>0,IFERROR(S8/$D$11,0),0)+$L$4*IFERROR(T8,0)-$L$5*IFERROR(U8,0)-$L$6*MAX(0,IFERROR(R8,0)-$L$7)+ROW()/1000000) | W8: =IFERROR(INDEX(GERAL[LADO],7),"") -> LADO 2 | Y8: =IFERROR(IF(INDEX(GERAL[PONTO],M8)="","",INDEX(GERAL[PONTO],M8)),"") -> 5 | Z8: =IF(Y8="","",IFERROR(INDEX(GERAL[ACUMULADA],7),0)) -> 80.1256 | AA8: =IF(Z8="","",$B$31-Z8) -> 25.9064 | AB8: =IF(Z8="","",IF(Z8*1.15<=30,30,IF(Z8*1.15<=45,45,IF(Z8*1.15<=75,75,IF(Z8*1.15<=112.5,112.5,IF(Z8*1.15<=150,150,IF(Z8*1.15<=225,225,300))))))) -> 112.5 | AC8: =IF(AB8="","",IFERROR(Z8/AB8,0)) -> 0.71222756 | AD8: =IF(Y8="","",IFERROR(INDEX(DIR_ATUAL[QT %],MATCH(Y8,DIR_ATUAL[PONTO],0)),0)) -> 0.068385447 | AE8: =IF(Z8="","",IFERROR(1-ABS(Z8-AA8)/$B$31,0)) -> 0.48865248 | AF8: =IF(Y8="","",IF($E$9>$E$8,IFERROR((INDEX(GERAL[SNAP],7)-$E$8)/($E$9-$E$8),0),0)) -> 0 | AG8: =IF(OR(Y8="",AH8<>"LADO 2"),"",$L$2*IFERROR(Z8/$B$31,0)+$L$3*IF($D$31>0,IFERROR(AD8/$D$31,0),0)+$L$4*IFERROR(AE8,0)-$L$5*IFERROR(AF8,0)-$L$6*MAX(0,IFERROR(AC8,0)-$L$7)+ROW()/1000000) -> 0.63510716 | AH8: =IFERROR(INDEX(GERAL[LADO],7),"") -> LADO 2
B9: =IFERROR(MAXIFS(GERAL[SNAP],GERAL[LADO],"ESQUERDO"),1) -> 1 | E9: =IFERROR(MAXIFS(GERAL[SNAP],GERAL[LADO],"DIREITO"),1) -> 1 | M9: 8 | N9: =IFERROR(IF(INDEX(GERAL[PONTO],M9)="","",INDEX(GERAL[PONTO],M9)),"") -> 6 | O9: =IF(N9="","",IFERROR(INDEX(GERAL[ACUMULADA],8),0)) -> 61.1752 | P9: =IF(O9="","",$B$11-O9) -> -20.5296 | Q9: =IF(O9="","",IF(O9*1.15<=30,30,IF(O9*1.15<=45,45,IF(O9*1.15<=75,75,IF(O9*1.15<=112.5,112.5,IF(O9*1.15<=150,150,IF(O9*1.15<=225,225,300))))))) -> 75 | R9: =IF(Q9="","",IFERROR(O9/Q9,0)) -> 0.81566933 | S9: =IF(N9="","",IFERROR(INDEX(Tabela7[QT %],MATCH(N9,Tabela7[PONTO],0)),0)) -> 0 | T9: =IF(O9="","",IFERROR(1-ABS(O9-P9)/$B$11,0)) -> -1.0101758 | U9: =IF(N9="","",IF($B$9>$B$8,IFERROR((INDEX(GERAL[SNAP],8)-$B$8)/($B$9-$B$8),0),0)) -> 0 | V9: =IF(OR(N9="",W9<>"LADO 1"),"",$L$2*IFERROR(O9/$B$11,0)+$L$3*IF($D$11>0,IFERROR(S9/$D$11,0),0)+$L$4*IFERROR(T9,0)-$L$5*IFERROR(U9,0)-$L$6*MAX(0,IFERROR(R9,0)-$L$7)+ROW()/1000000) | W9: =IFERROR(INDEX(GERAL[LADO],8),"") -> LADO 2 | Y9: =IFERROR(IF(INDEX(GERAL[PONTO],M9)="","",INDEX(GERAL[PONTO],M9)),"") -> 6 | Z9: =IF(Y9="","",IFERROR(INDEX(GERAL[ACUMULADA],8),0)) -> 61.1752 | AA9: =IF(Z9="","",$B$31-Z9) -> 44.8568 | AB9: =IF(Z9="","",IF(Z9*1.15<=30,30,IF(Z9*1.15<=45,45,IF(Z9*1.15<=75,75,IF(Z9*1.15<=112.5,112.5,IF(Z9*1.15<=150,150,IF(Z9*1.15<=225,225,300))))))) -> 75 | AC9: =IF(AB9="","",IFERROR(Z9/AB9,0)) -> 0.81566933 | AD9: =IF(Y9="","",IFERROR(INDEX(DIR_ATUAL[QT %],MATCH(Y9,DIR_ATUAL[PONTO],0)),0)) -> 0.070945192 | AE9: =IF(Z9="","",IFERROR(1-ABS(Z9-AA9)/$B$31,0)) -> 0.84609929 | AF9: =IF(Y9="","",IF($E$9>$E$8,IFERROR((INDEX(GERAL[SNAP],8)-$E$8)/($E$9-$E$8),0),0)) -> 0 | AG9: =IF(OR(Y9="",AH9<>"LADO 2"),"",$L$2*IFERROR(Z9/$B$31,0)+$L$3*IF($D$31>0,IFERROR(AD9/$D$31,0),0)+$L$4*IFERROR(AE9,0)-$L$5*IFERROR(AF9,0)-$L$6*MAX(0,IFERROR(AC9,0)-$L$7)+ROW()/1000000) -> 0.60016947 | AH9: =IFERROR(INDEX(GERAL[LADO],8),"") -> LADO 2
A10: LADO 1 - TOP CORTES | M10: 9 | N10: =IFERROR(IF(INDEX(GERAL[PONTO],M10)="","",INDEX(GERAL[PONTO],M10)),"") -> 7 | O10: =IF(N10="","",IFERROR(INDEX(GERAL[ACUMULADA],9),0)) -> 61.1752 | P10: =IF(O10="","",$B$11-O10) -> -20.5296 | Q10: =IF(O10="","",IF(O10*1.15<=30,30,IF(O10*1.15<=45,45,IF(O10*1.15<=75,75,IF(O10*1.15<=112.5,112.5,IF(O10*1.15<=150,150,IF(O10*1.15<=225,225,300))))))) -> 75 | R10: =IF(Q10="","",IFERROR(O10/Q10,0)) -> 0.81566933 | S10: =IF(N10="","",IFERROR(INDEX(Tabela7[QT %],MATCH(N10,Tabela7[PONTO],0)),0)) -> 0 | T10: =IF(O10="","",IFERROR(1-ABS(O10-P10)/$B$11,0)) -> -1.0101758 | U10: =IF(N10="","",IF($B$9>$B$8,IFERROR((INDEX(GERAL[SNAP],9)-$B$8)/($B$9-$B$8),0),0)) -> 0 | V10: =IF(OR(N10="",W10<>"LADO 1"),"",$L$2*IFERROR(O10/$B$11,0)+$L$3*IF($D$11>0,IFERROR(S10/$D$11,0),0)+$L$4*IFERROR(T10,0)-$L$5*IFERROR(U10,0)-$L$6*MAX(0,IFERROR(R10,0)-$L$7)+ROW()/1000000) | W10: =IFERROR(INDEX(GERAL[LADO],9),"") -> LADO 2 | Y10: =IFERROR(IF(INDEX(GERAL[PONTO],M10)="","",INDEX(GERAL[PONTO],M10)),"") -> 7 | Z10: =IF(Y10="","",IFERROR(INDEX(GERAL[ACUMULADA],9),0)) -> 61.1752 | AA10: =IF(Z10="","",$B$31-Z10) -> 44.8568 | AB10: =IF(Z10="","",IF(Z10*1.15<=30,30,IF(Z10*1.15<=45,45,IF(Z10*1.15<=75,75,IF(Z10*1.15<=112.5,112.5,IF(Z10*1.15<=150,150,IF(Z10*1.15<=225,225,300))))))) -> 75 | AC10: =IF(AB10="","",IFERROR(Z10/AB10,0)) -> 0.81566933 | AD10: =IF(Y10="","",IFERROR(INDEX(DIR_ATUAL[QT %],MATCH(Y10,DIR_ATUAL[PONTO],0)),0)) -> 0.10219776 | AE10: =IF(Z10="","",IFERROR(1-ABS(Z10-AA10)/$B$31,0)) -> 0.84609929 | AF10: =IF(Y10="","",IF($E$9>$E$8,IFERROR((INDEX(GERAL[SNAP],9)-$E$8)/($E$9-$E$8),0),0)) -> 0 | AG10: =IF(OR(Y10="",AH10<>"LADO 2"),"",$L$2*IFERROR(Z10/$B$31,0)+$L$3*IF($D$31>0,IFERROR(AD10/$D$31,0),0)+$L$4*IFERROR(AE10,0)-$L$5*IFERROR(AF10,0)-$L$6*MAX(0,IFERROR(AC10,0)-$L$7)+ROW()/1000000) -> 0.78457727 | AH10: =IFERROR(INDEX(GERAL[LADO],9),"") -> LADO 2
